Workbook

Sheet 안내
A1: 1팀 수신·접수 일일점검 / 주간 자동집계 — 사용안내
A4: [매일 하는 일]
A5: 1 | B5: 출근하면 팀원 이름 시트(이재희·김가은·김보혜·박언정·강아름·정민지)를 연다.
A6: 2 | B6: 전날 날짜 행을 찾아 노란색 칸 3개만 입력한다 → C열 수신 실적, D열 접수 실적, E열 비고.
A7: 3 | B7: 근무를 안 한 날(휴무·연차)은 실적을 비우고 E열 비고에서 값을 선택한다. 비고 선택값: 휴무 / 연차 / 오전반차 / 오후반차 / 입사전 / 기타
A8: 4 | B8: 나머지(목표·달성률·달성여부·주간 평균·주간 달성여부)는 전부 자동 계산된다.
A9: 5 | B9: 오늘 날짜 행은 주황색으로 자동 표시된다.
A11: [주간 보고서]
A12: · | B12: 각 팀원 시트 오른쪽(M~X열)에 그 사람의 주차별 집계가 자동으로 만들어진다.
A13: · | B13: '주간 점검 보고서' 시트에 6명 × 20주차가 한 장으로 모여 있다. 여기도 전부 자동.
A14: · | B14: 사람이 직접 쓰는 칸은 '주간 피드백내용'(팀원 시트 X열) 하나뿐이다. 여기에 쓰면 통합 보고서에도 그대로 반영된다.
A16: [계산 기준]
A17: · | B17: 주간 수신/접수 = 그 주 '입력된 날'의 평균. 휴무·연차 등 실적이 빈 날은 평균에서 자동 제외된다.
A18: · | B18: 주간 목표도 그 주 '입력된 날'의 일일 목표 평균으로 계산된다. 반차가 낀 주는 주간 목표가 자동으로 내려간다.
A19: · | B19: 달성여부 = 실적 ≥ 목표 이면 '달성', 아니면 '미달'. 실적이 비어 있으면 비고값(휴무·연차 등) 또는 '미입력'으로 표시.
A20: · | B20: 오전반차·오후반차는 비고를 선택하면 그날 목표가 자동으로 절반(수신 25 또는 22.5 / 접수 32.5 또는 30)으로 줄어든다. 실적은 그대로 입력하면 된다.
A21: · | B21: 목표: 1년 이상 = 수신 50 / 접수 65, 1년 미만 = 수신 45 / 접수 60.
A22: · | B22: 목표를 바꾸려면 각 팀원 시트의 D2(수신 목표)·F2(접수 목표)만 고치면 전 기간에 반영된다.
A23: · | B23: 근무연차가 바뀌면 각 팀원 시트 B2를 고치고 D2·F2 목표를 함께 조정한다.

Sheet 이재희
A1: 1팀 수신·접수 점검표 — 이재희 | M1: 주간 자동집계 — 이재희
A2: 근무연차 | B2: 1년 이상 | C2: 수신 목표 | D2: 50 | E2: 접수 목표 | F2: 65
A3: ※ 노란색 칸(수신 실적 · 접수 실적 · 비고)만 입력하세요. 나머지는 자동 계산됩니다. | M3: ※ 자동 집계 구간입니다. 직접 입력하는 칸은 '주간 피드백내용'(X열) 하나뿐입니다.
A4: 날짜 | B4: 요일 | C4: 수신 실적 | D4: 접수 실적 | E4: 비고 | F4: 수신 목표 | G4: 수신 달성률 | H4: 수신 달성여부 | I4: 접수 목표 | J4: 접수 달성률 | K4: 접수 달성여부 | M4: 주차 | N4: 시작일 | O4: 종료일 | P4: 수신 목표 | Q4: 주간 수신 평균 | R4: 수신 달성률 | S4: 수신 달성여부 | T4: 접수 목표 | U4: 주간 접수 평균 | V4: 접수 달성률 | W4: 접수 달성여부 | X4: 주간 피드백내용
A5: 46266 | B5: 화 | C5: 21 | D5: 69 | F5: =IF(OR($E5="오전반차",$E5="오후반차"),$D$2/2,$D$2) -> 50 | G5: =IF($C5="","",$C5/$F5) -> 0.42 | H5: =IF($C5="",IF($E5="","미입력",$E5),IF($C5>=$F5,"달성","미달")) -> 미달 | I5: =IF(OR($E5="오전반차",$E5="오후반차"),$F$2/2,$F$2) -> 65 | J5: =IF($D5="","",$D5/$I5) -> 1.0615385 | K5: =IF($D5="",IF($E5="","미입력",$E5),IF($D5>=$I5,"달성","미달")) -> 달성 | M5: 9월 1주차 | N5: 46266 | O5: 46271 | P5: =IFERROR(SUMPRODUCT(($A$5:$A$126>=$N5)*($A$5:$A$126<=$O5)*ISNUMBER($C$5:$C$126)*$F$5:$F$126)/SUMPRODUCT(($A$5:$A$126>=$N5)*($A$5:$A$126<=$O5)*ISNUMBER($C$5:$C$126)),"") -> 50 | Q5: =IFERROR(AVERAGEIFS($C$5:$C$126,$A$5:$A$126,">="&$N5,$A$5:$A$126,"<="&$O5),"") -> 37 | R5: =IF(OR($Q5="",$P5=""),"",$Q5/$P5) -> 0.74 | S5: =IF(OR($Q5="",$P5=""),"미입력",IF($Q5>=$P5,"달성","미달")) -> 미달 | T5: =IFERROR(SUMPRODUCT(($A$5:$A$126>=$N5)*($A$5:$A$126<=$O5)*ISNUMBER($D$5:$D$126)*$I$5:$I$126)/SUMPRODUCT(($A$5:$A$126>=$N5)*($A$5:$A$126<=$O5)*ISNUMBER($D$5:$D$126)),"") -> 65 | U5: =IFERROR(AVERAGEIFS($D$5:$D$126,$A$5:$A$126,">="&$N5,$A$5:$A$126,"<="&$O5),"") -> 62.2 | V5: =IF(OR($U5="",$T5=""),"",$U5/$T5) -> 0.95692308 | W5: =IF(OR($U5="",$T5=""),"미입력",IF($U5>=$T5,"달성","미달")) -> 미달 | X5: /
A6: 46267 | B6: 수 | C6: 31 | D6: 52 | F6: =IF(OR($E6="오전반차",$E6="오후반차"),$D$2/2,$D$2) -> 50 | G6: =IF($C6="","",$C6/$F6) -> 0.62 | H6: =IF($C6="",IF($E6="","미입력",$E6),IF($C6>=$F6,"달성","미달")) -> 미달 | I6: =IF(OR($E6="오전반차",$E6="오후반차"),$F$2/2,$F$2) -> 65 | J6: =IF($D6="","",$D6/$I6) -> 0.8 | K6: =IF($D6="",IF($E6="","미입력",$E6),IF($D6>=$I6,"달성","미달")) -> 미달 | M6: 9월 2주차 | N6: 46272 | O6: 46278 | P6: =IFERROR(SUMPRODUCT(($A$5:$A$126>=$N6)*($A$5:$A$126<=$O6)*ISNUMBER($C$5:$C$126)*$F$5:$F$126)/SUMPRODUCT(($A$5:$A$126>=$N6)*($A$5:$A$126<=$O6)*ISNUMBER($C$5:$C$126)),"") -> 50 | Q6: =IFERROR(AVERAGEIFS($C$5:$C$126,$A$5:$A$126,">="&$N6,$A$5:$A$126,"<="&$O6),"") -> 41.8 | R6: =IF(OR($Q6="",$P6=""),"",$Q6/$P6) -> 0.836 | S6: =IF(OR($Q6="",$P6=""),"미입력",IF($Q6>=$P6,"달성","미달")) -> 미달 | T6: =IFERROR(SUMPRODUCT(($A$5:$A$126>=$N6)*($A$5:$A$126<=$O6)*ISNUMBER($D$5:$D$126)*$I$5:$I$126)/SUMPRODUCT(($A$5:$A$126>=$N6)*($A$5:$A$126<=$O6)*ISNUMBER($D$5:$D$126)),"") -> 65 | U6: =IFERROR(AVERAGEIFS($D$5:$D$126,$A$5:$A$126,">="&$N6,$A$5:$A$126,"<="&$O6),"") -> 54 | V6: =IF(OR($U6="",$T6=""),"",$U6/$T6) -> 0.83076923 | W6: =IF(OR($U6="",$T6=""),"미입력",IF($U6>=$T6,"달성","미달")) -> 미달 | X6: /
A7: 46268 | B7: 목 | E7: 휴무 | F7: =IF(OR($E7="오전반차",$E7="오후반차"),$D$2/2,$D$2) -> 50 | G7: =IF($C7="","",$C7/$F7) | H7: =IF($C7="",IF($E7="","미입력",$E7),IF($C7>=$F7,"달성","미달")) -> 휴무 | I7: =IF(OR($E7="오전반차",$E7="오후반차"),$F$2/2,$F$2) -> 65 | J7: =IF($D7="","",$D7/$I7) | K7: =IF($D7="",IF($E7="","미입력",$E7),IF($D7>=$I7,"달성","미달")) -> 휴무 | M7: 9월 3주차 | N7: 46279 | O7: 46285 | P7: =IFERROR(SUMPRODUCT(($A$5:$A$126>=$N7)*($A$5:$A$126<=$O7)*ISNUMBER($C$5:$C$126)*$F$5:$F$126)/SUMPRODUCT(($A$5:$A$126>=$N7)*($A$5:$A$126<=$O7)*ISNUMBER($C$5:$C$126)),"") -> 50 | Q7: =IFERROR(AVERAGEIFS($C$5:$C$126,$A$5:$A$126,">="&$N7,$A$5:$A$126,"<="&$O7),"") -> 30.5 | R7: =IF(OR($Q7="",$P7=""),"",$Q7/$P7) -> 0.61 | S7: =IF(OR($Q7="",$P7=""),"미입력",IF($Q7>=$P7,"달성","미달")) -> 미달 | T7: =IFERROR(SUMPRODUCT(($A$5:$A$126>=$N7)*($A$5:$A$126<=$O7)*ISNUMBER($D$5:$D$126)*$I$5:$I$126)/SUMPRODUCT(($A$5:$A$126>=$N7)*($A$5:$A$126<=$O7)*ISNUMBER($D$5:$D$126)),"") -> 65 | U7: =IFERROR(AVERAGEIFS($D$5:$D$126,$A$5:$A$126,">="&$N7,$A$5:$A$126,"<="&$O7),"") -> 57.333333 | V7: =IF(OR($U7="",$T7=""),"",$U7/$T7) -> 0.88205128 | W7: =IF(OR($U7="",$T7=""),"미입력",IF($U7>=$T7,"달성","미달")) -> 미달 | X7: /
A8: 46269 | B8: 금 | C8: 73 | D8: 122 | F8: =IF(OR($E8="오전반차",$E8="오후반차"),$D$2/2,$D$2) -> 50 | G8: =IF($C8="","",$C8/$F8) -> 1.46 | H8: =IF($C8="",IF($E8="","미입력",$E8),IF($C8>=$F8,"달성","미달")) -> 달성 | I8: =IF(OR($E8="오전반차",$E8="오후반차"),$F$2/2,$F$2) -> 65 | J8: =IF($D8="","",$D8/$I8) -> 1.8769231 | K8: =IF($D8="",IF($E8="","미입력",$E8),IF($D8>=$I8,"달성","미달")) -> 달성 | M8: 9월 4주차 | N8: 46286 | O8: 46292 | P8: =IFERROR(SUMPRODUCT(($A$5:$A$126>=$N8)*($A$5:$A$126<=$O8)*ISNUMBER($C$5:$C$126)*$F$5:$F$126)/SUMPRODUCT(($A$5:$A$126>=$N8)*($A$5:$A$126<=$O8)*ISNUMBER($C$5:$C$126)),"") -> 50 | Q8: =IFERROR(AVERAGEIFS($C$5:$C$126,$A$5:$A$126,">="&$N8,$A$5:$A$126,"<="&$O8),"") -> 17.4 | R8: =IF(OR($Q8="",$P8=""),"",$Q8/$P8) -> 0.348 | S8: =IF(OR($Q8="",$P8=""),"미입력",IF($Q8>=$P8,"달성","미달")) -> 미달 | T8: =IFERROR(SUMPRODUCT(($A$5:$A$126>=$N8)*($A$5:$A$126<=$O8)*ISNUMBER($D$5:$D$126)*$I$5:$I$126)/SUMPRODUCT(($A$5:$A$126>=$N8)*($A$5:$A$126<=$O8)*ISNUMBER($D$5:$D$126)),"") -> 65 | U8: =IFERROR(AVERAGEIFS($D$5:$D$126,$A$5:$A$126,">="&$N8,$A$5:$A$126,"<="&$O8),"") -> 32.4 | V8: =IF(OR($U8="",$T8=""),"",$U8/$T8) -> 0.49846154 | W8: =IF(OR($U8="",$T8=""),"미입력",IF($U8>=$T8,"달성","미달")) -> 미달 | X8: /
A9: 46270 | B9: 토 | C9: 24 | D9: 33 | F9: =IF(OR($E9="오전반차",$E9="오후반차"),$D$2/2,$D$2) -> 50 | G9: =IF($C9="","",$C9/$F9) -> 0.48 | H9: =IF($C9="",IF($E9="","미입력",$E9),IF($C9>=$F9,"달성","미달")) -> 미달 | I9: =IF(OR($E9="오전반차",$E9="오후반차"),$F$2/2,$F$2) -> 65 | J9: =IF($D9="","",$D9/$I9) -> 0.50769231 | K9: =IF($D9="",IF($E9="","미입력",$E9),IF($D9>=$I9,"달성","미달")) -> 미달 | M9: 9월 5주차 | N9: 46293 | O9: 46299 | P9: =IFERROR(SUMPRODUCT(($A$5:$A$126>=$N9)*($A$5:$A$126<=$O9)*ISNUMBER($C$5:$C$126)*$F$5:$F$126)/SUMPRODUCT(($A$5:$A$126>=$N9)*($A$5:$A$126<=$O9)*ISNUMBER($C$5:$C$126)),"") -> 50 | Q9: =IFERROR(AVERAGEIFS($C$5:$C$126,$A$5:$A$126,">="&$N9,$A$5:$A$126,"<="&$O9),"") -> 27.75 | R9: =IF(OR($Q9="",$P9=""),"",$Q9/$P9) -> 0.555 | S9: =IF(OR($Q9="",$P9=""),"미입력",IF($Q9>=$P9,"달성","미달")) -> 미달 | T9: =IFERROR(SUMPRODUCT(($A$5:$A$126>=$N9)*($A$5:$A$126<=$O9)*ISNUMBER($D$5:$D$126)*$I$5:$I$126)/SUMPRODUCT(($A$5:$A$126>=$N9)*($A$5:$A$126<=$O9)*ISNUMBER($D$5:$D$126)),"") -> 65 | U9: =IFERROR(AVERAGEIFS($D$5:$D$126,$A$5:$A$126,">="&$N9,$A$5:$A$126,"<="&$O9),"") -> 43 | V9: =IF(OR($U9="",$T9=""),"",$U9/$T9) -> 0.66153846 | W9: =IF(OR($U9="",$T9=""),"미입력",IF($U9>=$T9,"달성","미달")) -> 미달 | X9: /
A10: 46271 | B10: 일 | C10: 36 | D10: 35 | F10: =IF(OR($E10="오전반차",$E10="오후반차"),$D$2/2,$D$2) -> 50 | G10: =IF($C10="","",$C10/$F10) -> 0.72 | H10: =IF($C10="",IF($E10="","미입력",$E10),IF($C10>=$F10,"달성","미달")) -> 미달 | I10: =IF(OR($E10="오전반차",$E10="오후반차"),$F$2/2,$F$2) -> 65 | J10: =IF($D10="","",$D10/$I10) -> 0.53846154 | K10: =IF($D10="",IF($E10="","미입력",$E10),IF($D10>=$I10,"달성","미달")) -> 미달 | M10: 10월 2주차 | N10: 46300 | O10: 46306 | P10: =IFERROR(SUMPRODUCT(($A$5:$A$126>=$N10)*($A$5:$A$126<=$O10)*ISNUMBER($C$5:$C$126)*$F$5:$F$126)/SUMPRODUCT(($A$5:$A$126>=$N10)*($A$5:$A$126<=$O10)*ISNUMBER($C$5:$C$126)),"") | Q10: =IFERROR(AVERAGEIFS($C$5:$C$126,$A$5:$A$126,">="&$N10,$A$5:$A$126,"<="&$O10),"") | R10: =IF(OR($Q10="",$P10=""),"",$Q10/$P10) | S10: =IF(OR($Q10="",$P10=""),"미입력",IF($Q10>=$P10,"달성","미달")) -> 미입력 | T10: =IFERROR(SUMPRODUCT(($A$5:$A$126>=$N10)*($A$5:$A$126<=$O10)*ISNUMBER($D$5:$D$126)*$I$5:$I$126)/SUMPRODUCT(($A$5:$A$126>=$N10)*($A$5:$A$126<=$O10)*ISNUMBER($D$5:$D$126)),"") | U10: =IFERROR(AVERAGEIFS($D$5:$D$126,$A$5:$A$126,">="&$N10,$A$5:$A$126,"<="&$O10),"") | V10: =IF(OR($U10="",$T10=""),"",$U10/$T10) | W10: =IF(OR($U10="",$T10=""),"미입력",IF($U10>=$T10,"달성","미달")) -> 미입력
A11: 46272 | B11: 월 | E11: 휴무 | F11: =IF(OR($E11="오전반차",$E11="오후반차"),$D$2/2,$D$2) -> 50 | G11: =IF($C11="","",$C11/$F11) | H11: =IF($C11="",IF($E11="","미입력",$E11),IF($C11>=$F11,"달성","미달")) -> 휴무 | I11: =IF(OR($E11="오전반차",$E11="오후반차"),$F$2/2,$F$2) -> 65 | J11: =IF($D11="","",$D11/$I11) | K11: =IF($D11="",IF($E11="","미입력",$E11),IF($D11>=$I11,"달성","미달")) -> 휴무 | M11: 10월 3주차 | N11: 46302 | O11: 46308 | P11: =IFERROR(SUMPRODUCT(($A$5:$A$126>=$N11)*($A$5:$A$126<=$O11)*ISNUMBER($C$5:$C$126)*$F$5:$F$126)/SUMPRODUCT(($A$5:$A$126>=$N11)*($A$5:$A$126<=$O11)*ISNUMBER($C$5:$C$126)),"") | Q11: =IFERROR(AVERAGEIFS($C$5:$C$126,$A$5:$A$126,">="&$N11,$A$5:$A$126,"<="&$O11),"") | R11: =IF(OR($Q11="",$P11=""),"",$Q11/$P11) | S11: =IF(OR($Q11="",$P11=""),"미입력",IF($Q11>=$P11,"달성","미달")) -> 미입력 | T11: =IFERROR(SUMPRODUCT(($A$5:$A$126>=$N11)*($A$5:$A$126<=$O11)*ISNUMBER($D$5:$D$126)*$I$5:$I$126)/SUMPRODUCT(($A$5:$A$126>=$N11)*($A$5:$A$126<=$O11)*ISNUMBER($D$5:$D$126)),"") | U11: =IFERROR(AVERAGEIFS($D$5:$D$126,$A$5:$A$126,">="&$N11,$A$5:$A$126,"<="&$O11),"") | V11: =IF(OR($U11="",$T11=""),"",$U11/$T11) | W11: =IF(OR($U11="",$T11=""),"미입력",IF($U11>=$T11,"달성","미달")) -> 미입력
A12: 46273 | B12: 화 | C12: 45 | D12: 54 | F12: =IF(OR($E12="오전반차",$E12="오후반차"),$D$2/2,$D$2) -> 50 | G12: =IF($C12="","",$C12/$F12) -> 0.9 | H12: =IF($C12="",IF($E12="","미입력",$E12),IF($C12>=$F12,"달성","미달")) -> 미달 | I12: =IF(OR($E12="오전반차",$E12="오후반차"),$F$2/2,$F$2) -> 65 | J12: =IF($D12="","",$D12/$I12) -> 0.83076923 | K12: =IF($D12="",IF($E12="","미입력",$E12),IF($D12>=$I12,"달성","미달")) -> 미달 | M12: 10월 4주차 | N12: 46309 | O12: 46315 | P12: =IFERROR(SUMPRODUCT(($A$5:$A$126>=$N12)*($A$5:$A$126<=$O12)*ISNUMBER($C$5:$C$126)*$F$5:$F$126)/SUMPRODUCT(($A$5:$A$126>=$N12)*($A$5:$A$126<=$O12)*ISNUMBER($C$5:$C$126)),"") | Q12: =IFERROR(AVERAGEIFS($C$5:$C$126,$A$5:$A$126,">="&$N12,$A$5:$A$126,"<="&$O12),"") | R12: =IF(OR($Q12="",$P12=""),"",$Q12/$P12) | S12: =IF(OR($Q12="",$P12=""),"미입력",IF($Q12>=$P12,"달성","미달")) -> 미입력 | T12: =IFERROR(SUMPRODUCT(($A$5:$A$126>=$N12)*($A$5:$A$126<=$O12)*ISNUMBER($D$5:$D$126)*$I$5:$I$126)/SUMPRODUCT(($A$5:$A$126>=$N12)*($A$5:$A$126<=$O12)*ISNUMBER($D$5:$D$126)),"") | U12: =IFERROR(AVERAGEIFS($D$5:$D$126,$A$5:$A$126,">="&$N12,$A$5:$A$126,"<="&$O12),"") | V12: =IF(OR($U12="",$T12=""),"",$U12/$T12) | W12: =IF(OR($U12="",$T12=""),"미입력",IF($U12>=$T12,"달성","미달")) -> 미입력
A13: 46274 | B13: 수 | C13: 37 | D13: 47 | F13: =IF(OR($E13="오전반차",$E13="오후반차"),$D$2/2,$D$2) -> 50 | G13: =IF($C13="","",$C13/$F13) -> 0.74 | H13: =IF($C13="",IF($E13="","미입력",$E13),IF($C13>=$F13,"달성","미달")) -> 미달 | I13: =IF(OR($E13="오전반차",$E13="오후반차"),$F$2/2,$F$2) -> 65 | J13: =IF($D13="","",$D13/$I13) -> 0.72307692 | K13: =IF($D13="",IF($E13="","미입력",$E13),IF($D13>=$I13,"달성","미달")) -> 미달 | M13: 10월 5주차 | N13: 46316 | O13: 46322 | P13: =IFERROR(SUMPRODUCT(($A$5:$A$126>=$N13)*($A$5:$A$126<=$O13)*ISNUMBER($C$5:$C$126)*$F$5:$F$126)/SUMPRODUCT(($A$5:$A$126>=$N13)*($A$5:$A$126<=$O13)*ISNUMBER($C$5:$C$126)),"") | Q13: =IFERROR(AVERAGEIFS($C$5:$C$126,$A$5:$A$126,">="&$N13,$A$5:$A$126,"<="&$O13),"") | R13: =IF(OR($Q13="",$P13=""),"",$Q13/$P13) | S13: =IF(OR($Q13="",$P13=""),"미입력",IF($Q13>=$P13,"달성","미달")) -> 미입력 | T13: =IFERROR(SUMPRODUCT(($A$5:$A$126>=$N13)*($A$5:$A$126<=$O13)*ISNUMBER($D$5:$D$126)*$I$5:$I$126)/SUMPRODUCT(($A$5:$A$126>=$N13)*($A$5:$A$126<=$O13)*ISNUMBER($D$5:$D$126)),"") | U13: =IFERROR(AVERAGEIFS($D$5:$D$126,$A$5:$A$126,">="&$N13,$A$5:$A$126,"<="&$O13),"") | V13: =IF(OR($U13="",$T13=""),"",$U13/$T13) | W13: =IF(OR($U13="",$T13=""),"미입력",IF($U13>=$T13,"달성","미달")) -> 미입력
A14: 46275 | B14: 목 | C14: 20 | D14: 49 | F14: =IF(OR($E14="오전반차",$E14="오후반차"),$D$2/2,$D$2) -> 50 | G14: =IF($C14="","",$C14/$F14) -> 0.4 | H14: =IF($C14="",IF($E14="","미입력",$E14),IF($C14>=$F14,"달성","미달")) -> 미달 | I14: =IF(OR($E14="오전반차",$E14="오후반차"),$F$2/2,$F$2) -> 65 | J14: =IF($D14="","",$D14/$I14) -> 0.75384615 | K14: =IF($D14="",IF($E14="","미입력",$E14),IF($D14>=$I14,"달성","미달")) -> 미달 | N14: 46323 | O14: 46326 | P14: =IFERROR(SUMPRODUCT(($A$5:$A$126>=$N14)*($A$5:$A$126<=$O14)*ISNUMBER($C$5:$C$126)*$F$5:$F$126)/SUMPRODUCT(($A$5:$A$126>=$N14)*($A$5:$A$126<=$O14)*ISNUMBER($C$5:$C$126)),"") | Q14: =IFERROR(AVERAGEIFS($C$5:$C$126,$A$5:$A$126,">="&$N14,$A$5:$A$126,"<="&$O14),"") | R14: =IF(OR($Q14="",$P14=""),"",$Q14/$P14) | S14: =IF(OR($Q14="",$P14=""),"미입력",IF($Q14>=$P14,"달성","미달")) -> 미입력 | T14: =IFERROR(SUMPRODUCT(($A$5:$A$126>=$N14)*($A$5:$A$126<=$O14)*ISNUMBER($D$5:$D$126)*$I$5:$I$126)/SUMPRODUCT(($A$5:$A$126>=$N14)*($A$5:$A$126<=$O14)*ISNUMBER($D$5:$D$126)),"") | U14: =IFERROR(AVERAGEIFS($D$5:$D$126,$A$5:$A$126,">="&$N14,$A$5:$A$126,"<="&$O14),"") | V14: =IF(OR($U14="",$T14=""),"",$U14/$T14) | W14: =IF(OR($U14="",$T14=""),"미입력",IF($U14>=$T14,"달성","미달")) -> 미입력
A15: 46276 | B15: 금 | C15: 54 | D15: 74 | F15: =IF(OR($E15="오전반차",$E15="오후반차"),$D$2/2,$D$2) -> 50 | G15: =IF($C15="","",$C15/$F15) -> 1.08 | H15: =IF($C15="",IF($E15="","미입력",$E15),IF($C15>=$F15,"달성","미달")) -> 달성 | I15: =IF(OR($E15="오전반차",$E15="오후반차"),$F$2/2,$F$2) -> 65 | J15: =IF($D15="","",$D15/$I15) -> 1.1384615 | K15: =IF($D15="",IF($E15="","미입력",$E15),IF($D15>=$I15,"달성","미달")) -> 달성 | M15: 11월 1주차 | N15: 46327 | O15: 46332 | P15: =IFERROR(SUMPRODUCT(($A$5:$A$126>=$N15)*($A$5:$A$126<=$O15)*ISNUMBER($C$5:$C$126)*$F$5:$F$126)/SUMPRODUCT(($A$5:$A$126>=$N15)*($A$5:$A$126<=$O15)*ISNUMBER($C$5:$C$126)),"") | Q15: =IFERROR(AVERAGEIFS($C$5:$C$126,$A$5:$A$126,">="&$N15,$A$5:$A$126,"<="&$O15),"") | R15: =IF(OR($Q15="",$P15=""),"",$Q15/$P15) | S15: =IF(OR($Q15="",$P15=""),"미입력",IF($Q15>=$P15,"달성","미달")) -> 미입력 | T15: =IFERROR(SUMPRODUCT(($A$5:$A$126>=$N15)*($A$5:$A$126<=$O15)*ISNUMBER($D$5:$D$126)*$I$5:$I$126)/SUMPRODUCT(($A$5:$A$126>=$N15)*($A$5:$A$126<=$O15)*ISNUMBER($D$5:$D$126)),"") | U15: =IFERROR(AVERAGEIFS($D$5:$D$126,$A$5:$A$126,">="&$N15,$A$5:$A$126,"<="&$O15),"") | V15: =IF(OR($U15="",$T15=""),"",$U15/$T15) | W15: =IF(OR($U15="",$T15=""),"미입력",IF($U15>=$T15,"달성","미달")) -> 미입력
A16: 46277 | B16: 토 | C16: 53 | D16: 46 | F16: =IF(OR($E16="오전반차",$E16="오후반차"),$D$2/2,$D$2) -> 50 | G16: =IF($C16="","",$C16/$F16) -> 1.06 | H16: =IF($C16="",IF($E16="","미입력",$E16),IF($C16>=$F16,"달성","미달")) -> 달성 | I16: =IF(OR($E16="오전반차",$E16="오후반차"),$F$2/2,$F$2) -> 65 | J16: =IF($D16="","",$D16/$I16) -> 0.70769231 | K16: =IF($D16="",IF($E16="","미입력",$E16),IF($D16>=$I16,"달성","미달")) -> 미달 | M16: 11월 2주차 | N16: 46333 | O16: 46339 | P16: =IFERROR(SUMPRODUCT(($A$5:$A$126>=$N16)*($A$5:$A$126<=$O16)*ISNUMBER($C$5:$C$126)*$F$5:$F$126)/SUMPRODUCT(($A$5:$A$126>=$N16)*($A$5:$A$126<=$O16)*ISNUMBER($C$5:$C$126)),"") | Q16: =IFERROR(AVERAGEIFS($C$5:$C$126,$A$5:$A$126,">="&$N16,$A$5:$A$126,"<="&$O16),"") | R16: =IF(OR($Q16="",$P16=""),"",$Q16/$P16) | S16: =IF(OR($Q16="",$P16=""),"미입력",IF($Q16>=$P16,"달성","미달")) -> 미입력 | T16: =IFERROR(SUMPRODUCT(($A$5:$A$126>=$N16)*($A$5:$A$126<=$O16)*ISNUMBER($D$5:$D$126)*$I$5:$I$126)/SUMPRODUCT(($A$5:$A$126>=$N16)*($A$5:$A$126<=$O16)*ISNUMBER($D$5:$D$126)),"") | U16: =IFERROR(AVERAGEIFS($D$5:$D$126,$A$5:$A$126,">="&$N16,$A$5:$A$126,"<="&$O16),"") | V16: =IF(OR($U16="",$T16=""),"",$U16/$T16) | W16: =IF(OR($U16="",$T16=""),"미입력",IF($U16>=$T16,"달성","미달")) -> 미입력
A17: 46278 | B17: 일 | E17: 휴무 | F17: =IF(OR($E17="오전반차",$E17="오후반차"),$D$2/2,$D$2) -> 50 | G17: =IF($C17="","",$C17/$F17) | H17: =IF($C17="",IF($E17="","미입력",$E17),IF($C17>=$F17,"달성","미달")) -> 휴무 | I17: =IF(OR($E17="오전반차",$E17="오후반차"),$F$2/2,$F$2) -> 65 | J17: =IF($D17="","",$D17/$I17) | K17: =IF($D17="",IF($E17="","미입력",$E17),IF($D17>=$I17,"달성","미달")) -> 휴무 | M17: 11월 3주차 | N17: 46340 | O17: 46346 | P17: =IFERROR(SUMPRODUCT(($A$5:$A$126>=$N17)*($A$5:$A$126<=$O17)*ISNUMBER($C$5:$C$126)*$F$5:$F$126)/SUMPRODUCT(($A$5:$A$126>=$N17)*($A$5:$A$126<=$O17)*ISNUMBER($C$5:$C$126)),"") | Q17: =IFERROR(AVERAGEIFS($C$5:$C$126,$A$5:$A$126,">="&$N17,$A$5:$A$126,"<="&$O17),"") | R17: =IF(OR($Q17="",$P17=""),"",$Q17/$P17) | S17: =IF(OR($Q17="",$P17=""),"미입력",IF($Q17>=$P17,"달성","미달")) -> 미입력 | T17: =IFERROR(SUMPRODUCT(($A$5:$A$126>=$N17)*($A$5:$A$126<=$O17)*ISNUMBER($D$5:$D$126)*$I$5:$I$126)/SUMPRODUCT(($A$5:$A$126>=$N17)*($A$5:$A$126<=$O17)*ISNUMBER($D$5:$D$126)),"") | U17: =IFERROR(AVERAGEIFS($D$5:$D$126,$A$5:$A$126,">="&$N17,$A$5:$A$126,"<="&$O17),"") | V17: =IF(OR($U17="",$T17=""),"",$U17/$T17) | W17: =IF(OR($U17="",$T17=""),"미입력",IF($U17>=$T17,"달성","미달")) -> 미입력
A18: 46279 | B18: 월 | C18: 26 | D18: 73 | F18: =IF(OR($E18="오전반차",$E18="오후반차"),$D$2/2,$D$2) -> 50 | G18: =IF($C18="","",$C18/$F18) -> 0.52 | H18: =IF($C18="",IF($E18="","미입력",$E18),IF($C18>=$F18,"달성","미달")) -> 미달 | I18: =IF(OR($E18="오전반차",$E18="오후반차"),$F$2/2,$F$2) -> 65 | J18: =IF($D18="","",$D18/$I18) -> 1.1230769 | K18: =IF($D18="",IF($E18="","미입력",$E18),IF($D18>=$I18,"달성","미달")) -> 달성 | M18: 11월 4주차 | N18: 46347 | O18: 46353 | P18: =IFERROR(SUMPRODUCT(($A$5:$A$126>=$N18)*($A$5:$A$126<=$O18)*ISNUMBER($C$5:$C$126)*$F$5:$F$126)/SUMPRODUCT(($A$5:$A$126>=$N18)*($A$5:$A$126<=$O18)*ISNUMBER($C$5:$C$126)),"") | Q18: =IFERROR(AVERAGEIFS($C$5:$C$126,$A$5:$A$126,">="&$N18,$A$5:$A$126,"<="&$O18),"") | R18: =IF(OR($Q18="",$P18=""),"",$Q18/$P18) | S18: =IF(OR($Q18="",$P18=""),"미입력",IF($Q18>=$P18,"달성","미달")) -> 미입력 | T18: =IFERROR(SUMPRODUCT(($A$5:$A$126>=$N18)*($A$5:$A$126<=$O18)*ISNUMBER($D$5:$D$126)*$I$5:$I$126)/SUMPRODUCT(($A$5:$A$126>=$N18)*($A$5:$A$126<=$O18)*ISNUMBER($D$5:$D$126)),"") | U18: =IFERROR(AVERAGEIFS($D$5:$D$126,$A$5:$A$126,">="&$N18,$A$5:$A$126,"<="&$O18),"") | V18: =IF(OR($U18="",$T18=""),"",$U18/$T18) | W18: =IF(OR($U18="",$T18=""),"미입력",IF($U18>=$T18,"달성","미달")) -> 미입력
A19: 46280 | B19: 화 | C19: 20 | D19: 30 | F19: =IF(OR($E19="오전반차",$E19="오후반차"),$D$2/2,$D$2) -> 50 | G19: =IF($C19="","",$C19/$F19) -> 0.4 | H19: =IF($C19="",IF($E19="","미입력",$E19),IF($C19>=$F19,"달성","미달")) -> 미달 | I19: =IF(OR($E19="오전반차",$E19="오후반차"),$F$2/2,$F$2) -> 65 | J19: =IF($D19="","",$D19/$I19) -> 0.46153846 | K19: =IF($D19="",IF($E19="","미입력",$E19),IF($D19>=$I19,"달성","미달")) -> 미달 | M19: 11월 5주차 | N19: 46354 | O19: 46356 | P19: =IFERROR(SUMPRODUCT(($A$5:$A$126>=$N19)*($A$5:$A$126<=$O19)*ISNUMBER($C$5:$C$126)*$F$5:$F$126)/SUMPRODUCT(($A$5:$A$126>=$N19)*($A$5:$A$126<=$O19)*ISNUMBER($C$5:$C$126)),"") | Q19: =IFERROR(AVERAGEIFS($C$5:$C$126,$A$5:$A$126,">="&$N19,$A$5:$A$126,"<="&$O19),"") | R19: =IF(OR($Q19="",$P19=""),"",$Q19/$P19) | S19: =IF(OR($Q19="",$P19=""),"미입력",IF($Q19>=$P19,"달성","미달")) -> 미입력 | T19: =IFERROR(SUMPRODUCT(($A$5:$A$126>=$N19)*($A$5:$A$126<=$O19)*ISNUMBER($D$5:$D$126)*$I$5:$I$126)/SUMPRODUCT(($A$5:$A$126>=$N19)*($A$5:$A$126<=$O19)*ISNUMBER($D$5:$D$126)),"") | U19: =IFERROR(AVERAGEIFS($D$5:$D$126,$A$5:$A$126,">="&$N19,$A$5:$A$126,"<="&$O19),"") | V19: =IF(OR($U19="",$T19=""),"",$U19/$T19) | W19: =IF(OR($U19="",$T19=""),"미입력",IF($U19>=$T19,"달성","미달")) -> 미입력
A20: 46281 | B20: 수 | C20: 34 | D20: 72 | F20: =IF(OR($E20="오전반차",$E20="오후반차"),$D$2/2,$D$2) -> 50 | G20: =IF($C20="","",$C20/$F20) -> 0.68 | H20: =IF($C20="",IF($E20="","미입력",$E20),IF($C20>=$F20,"달성","미달")) -> 미달 | I20: =IF(OR($E20="오전반차",$E20="오후반차"),$F$2/2,$F$2) -> 65 | J20: =IF($D20="","",$D20/$I20) -> 1.1076923 | K20: =IF($D20="",IF($E20="","미입력",$E20),IF($D20>=$I20,"달성","미달")) -> 달성 | M20: 12월 1주차 | N20: 46357 | O20: 46362 | P20: =IFERROR(SUMPRODUCT(($A$5:$A$126>=$N20)*($A$5:$A$126<=$O20)*ISNUMBER($C$5:$C$126)*$F$5:$F$126)/SUMPRODUCT(($A$5:$A$126>=$N20)*($A$5:$A$126<=$O20)*ISNUMBER($C$5:$C$126)),"") | Q20: =IFERROR(AVERAGEIFS($C$5:$C$126,$A$5:$A$126,">="&$N20,$A$5:$A$126,"<="&$O20),"") | R20: =IF(OR($Q20="",$P20=""),"",$Q20/$P20) | S20: =IF(OR($Q20="",$P20=""),"미입력",IF($Q20>=$P20,"달성","미달")) -> 미입력 | T20: =IFERROR(SUMPRODUCT(($A$5:$A$126>=$N20)*($A$5:$A$126<=$O20)*ISNUMBER($D$5:$D$126)*$I$5:$I$126)/SUMPRODUCT(($A$5:$A$126>=$N20)*($A$5:$A$126<=$O20)*ISNUMBER($D$5:$D$126)),"") | U20: =IFERROR(AVERAGEIFS($D$5:$D$126,$A$5:$A$126,">="&$N20,$A$5:$A$126,"<="&$O20),"") | V20: =IF(OR($U20="",$T20=""),"",$U20/$T20) | W20: =IF(OR($U20="",$T20=""),"미입력",IF($U20>=$T20,"달성","미달")) -> 미입력
A21: 46282 | B21: 목 | C21: 24 | D21: 44 | F21: =IF(OR($E21="오전반차",$E21="오후반차"),$D$2/2,$D$2) -> 50 | G21: =IF($C21="","",$C21/$F21) -> 0.48 | H21: =IF($C21="",IF($E21="","미입력",$E21),IF($C21>=$F21,"달성","미달")) -> 미달 | I21: =IF(OR($E21="오전반차",$E21="오후반차"),$F$2/2,$F$2) -> 65 | J21: =IF($D21="","",$D21/$I21) -> 0.67692308 | K21: =IF($D21="",IF($E21="","미입력",$E21),IF($D21>=$I21,"달성","미달")) -> 미달 | M21: 12월 2주차 | N21: 46363 | O21: 46369 | P21: =IFERROR(SUMPRODUCT(($A$5:$A$126>=$N21)*($A$5:$A$126<=$O21)*ISNUMBER($C$5:$C$126)*$F$5:$F$126)/SUMPRODUCT(($A$5:$A$126>=$N21)*($A$5:$A$126<=$O21)*ISNUMBER($C$5:$C$126)),"") | Q21: =IFERROR(AVERAGEIFS($C$5:$C$126,$A$5:$A$126,">="&$N21,$A$5:$A$126,"<="&$O21),"") | R21: =IF(OR($Q21="",$P21=""),"",$Q21/$P21) | S21: =IF(OR($Q21="",$P21=""),"미입력",IF($Q21>=$P21,"달성","미달")) -> 미입력 | T21: =IFERROR(SUMPRODUCT(($A$5:$A$126>=$N21)*($A$5:$A$126<=$O21)*ISNUMBER($D$5:$D$126)*$I$5:$I$126)/SUMPRODUCT(($A$5:$A$126>=$N21)*($A$5:$A$126<=$O21)*ISNUMBER($D$5:$D$126)),"") | U21: =IFERROR(AVERAGEIFS($D$5:$D$126,$A$5:$A$126,">="&$N21,$A$5:$A$126,"<="&$O21),"") | V21: =IF(OR($U21="",$T21=""),"",$U21/$T21) | W21: =IF(OR($U21="",$T21=""),"미입력",IF($U21>=$T21,"달성","미달")) -> 미입력
A22: 46283 | B22: 금 | C22: 45 | D22: 87 | F22: =IF(OR($E22="오전반차",$E22="오후반차"),$D$2/2,$D$2) -> 50 | G22: =IF($C22="","",$C22/$F22) -> 0.9 | H22: =IF($C22="",IF($E22="","미입력",$E22),IF($C22>=$F22,"달성","미달")) -> 미달 | I22: =IF(OR($E22="오전반차",$E22="오후반차"),$F$2/2,$F$2) -> 65 | J22: =IF($D22="","",$D22/$I22) -> 1.3384615 | K22: =IF($D22="",IF($E22="","미입력",$E22),IF($D22>=$I22,"달성","미달")) -> 달성 | M22: 12월 3주차 | N22: 46370 | O22: 46376 | P22: =IFERROR(SUMPRODUCT(($A$5:$A$126>=$N22)*($A$5:$A$126<=$O22)*ISNUMBER($C$5:$C$126)*$F$5:$F$126)/SUMPRODUCT(($A$5:$A$126>=$N22)*($A$5:$A$126<=$O22)*ISNUMBER($C$5:$C$126)),"") | Q22: =IFERROR(AVERAGEIFS($C$5:$C$126,$A$5:$A$126,">="&$N22,$A$5:$A$126,"<="&$O22),"") | R22: =IF(OR($Q22="",$P22=""),"",$Q22/$P22) | S22: =IF(OR($Q22="",$P22=""),"미입력",IF($Q22>=$P22,"달성","미달")) -> 미입력 | T22: =IFERROR(SUMPRODUCT(($A$5:$A$126>=$N22)*($A$5:$A$126<=$O22)*ISNUMBER($D$5:$D$126)*$I$5:$I$126)/SUMPRODUCT(($A$5:$A$126>=$N22)*($A$5:$A$126<=$O22)*ISNUMBER($D$5:$D$126)),"") | U22: =IFERROR(AVERAGEIFS($D$5:$D$126,$A$5:$A$126,">="&$N22,$A$5:$A$126,"<="&$O22),"") | V22: =IF(OR($U22="",$T22=""),"",$U22/$T22) | W22: =IF(OR($U22="",$T22=""),"미입력",IF($U22>=$T22,"달성","미달")) -> 미입력
A23: 46284 | B23: 토 | E23: 휴무 | F23: =IF(OR($E23="오전반차",$E23="오후반차"),$D$2/2,$D$2) -> 50 | G23: =IF($C23="","",$C23/$F23) | H23: =IF($C23="",IF($E23="","미입력",$E23),IF($C23>=$F23,"달성","미달")) -> 휴무 | I23: =IF(OR($E23="오전반차",$E23="오후반차"),$F$2/2,$F$2) -> 65 | J23: =IF($D23="","",$D23/$I23) | K23: =IF($D23="",IF($E23="","미입력",$E23),IF($D23>=$I23,"달성","미달")) -> 휴무 | M23: 12월 4주차 | N23: 46377 | O23: 46383 | P23: =IFERROR(SUMPRODUCT(($A$5:$A$126>=$N23)*($A$5:$A$126<=$O23)*ISNUMBER($C$5:$C$126)*$F$5:$F$126)/SUMPRODUCT(($A$5:$A$126>=$N23)*($A$5:$A$126<=$O23)*ISNUMBER($C$5:$C$126)),"") | Q23: =IFERROR(AVERAGEIFS($C$5:$C$126,$A$5:$A$126,">="&$N23,$A$5:$A$126,"<="&$O23),"") | R23: =IF(OR($Q23="",$P23=""),"",$Q23/$P23) | S23: =IF(OR($Q23="",$P23=""),"미입력",IF($Q23>=$P23,"달성","미달")) -> 미입력 | T23: =IFERROR(SUMPRODUCT(($A$5:$A$126>=$N23)*($A$5:$A$126<=$O23)*ISNUMBER($D$5:$D$126)*$I$5:$I$126)/SUMPRODUCT(($A$5:$A$126>=$N23)*($A$5:$A$126<=$O23)*ISNUMBER($D$5:$D$126)),"") | U23: =IFERROR(AVERAGEIFS($D$5:$D$126,$A$5:$A$126,">="&$N23,$A$5:$A$126,"<="&$O23),"") | V23: =IF(OR($U23="",$T23=""),"",$U23/$T23) | W23: =IF(OR($U23="",$T23=""),"미입력",IF($U23>=$T23,"달성","미달")) -> 미입력
A24: 46285 | B24: 일 | C24: 34 | D24: 38 | F24: =IF(OR($E24="오전반차",$E24="오후반차"),$D$2/2,$D$2) -> 50 | G24: =IF($C24="","",$C24/$F24) -> 0.68 | H24: =IF($C24="",IF($E24="","미입력",$E24),IF($C24>=$F24,"달성","미달")) -> 미달 | I24: =IF(OR($E24="오전반차",$E24="오후반차"),$F$2/2,$F$2) -> 65 | J24: =IF($D24="","",$D24/$I24) -> 0.58461538 | K24: =IF($D24="",IF($E24="","미입력",$E24),IF($D24>=$I24,"달성","미달")) -> 미달 | M24: 12월 5주차 | N24: 46384 | O24: 46387 | P24: =IFERROR(SUMPRODUCT(($A$5:$A$126>=$N24)*($A$5:$A$126<=$O24)*ISNUMBER($C$5:$C$126)*$F$5:$F$126)/SUMPRODUCT(($A$5:$A$126>=$N24)*($A$5:$A$126<=$O24)*ISNUMBER($C$5:$C$126)),"") | Q24: =IFERROR(AVERAGEIFS($C$5:$C$126,$A$5:$A$126,">="&$N24,$A$5:$A$126,"<="&$O24),"") | R24: =IF(OR($Q24="",$P24=""),"",$Q24/$P24) | S24: =IF(OR($Q24="",$P24=""),"미입력",IF($Q24>=$P24,"달성","미달")) -> 미입력 | T24: =IFERROR(SUMPRODUCT(($A$5:$A$126>=$N24)*($A$5:$A$126<=$O24)*ISNUMBER($D$5:$D$126)*$I$5:$I$126)/SUMPRODUCT(($A$5:$A$126>=$N24)*($A$5:$A$126<=$O24)*ISNUMBER($D$5:$D$126)),"") | U24: =IFERROR(AVERAGEIFS($D$5:$D$126,$A$5:$A$126,">="&$N24,$A$5:$A$126,"<="&$O24),"") | V24: =IF(OR($U24="",$T24=""),"",$U24/$T24) | W24: =IF(OR($U24="",$T24=""),"미입력",IF($U24>=$T24,"달성","미달")) -> 미입력
A25: 46286 | B25: 월 | C25: 21 | D25: 35 | F25: =IF(OR($E25="오전반차",$E25="오후반차"),$D$2/2,$D$2) -> 50 | G25: =IF($C25="","",$C25/$F25) -> 0.42 | H25: =IF($C25="",IF($E25="","미입력",$E25),IF($C25>=$F25,"달성","미달")) -> 미달 | I25: =IF(OR($E25="오전반차",$E25="오후반차"),$F$2/2,$F$2) -> 65 | J25: =IF($D25="","",$D25/$I25) -> 0.53846154 | K25: =IF($D25="",IF($E25="","미입력",$E25),IF($D25>=$I25,"달성","미달")) -> 미달
A26: 46287 | B26: 화 | C26: 13 | D26: 27 | F26: =IF(OR($E26="오전반차",$E26="오후반차"),$D$2/2,$D$2) -> 50 | G26: =IF($C26="","",$C26/$F26) -> 0.26 | H26: =IF($C26="",IF($E26="","미입력",$E26),IF($C26>=$F26,"달성","미달")) -> 미달 | I26: =IF(OR($E26="오전반차",$E26="오후반차"),$F$2/2,$F$2) -> 65 | J26: =IF($D26="","",$D26/$I26) -> 0.41538462 | K26: =IF($D26="",IF($E26="","미입력",$E26),IF($D26>=$I26,"달성","미달")) -> 미달
A27: 46288 | B27: 수 | C27: 12 | D27: 18 | F27: =IF(OR($E27="오전반차",$E27="오후반차"),$D$2/2,$D$2) -> 50 | G27: =IF($C27="","",$C27/$F27) -> 0.24 | H27: =IF($C27="",IF($E27="","미입력",$E27),IF($C27>=$F27,"달성","미달")) -> 미달 | I27: =IF(OR($E27="오전반차",$E27="오후반차"),$F$2/2,$F$2) -> 65 | J27: =IF($D27="","",$D27/$I27) -> 0.27692308 | K27: =IF($D27="",IF($E27="","미입력",$E27),IF($D27>=$I27,"달성","미달")) -> 미달
A28: 46289 | B28: 목 | E28: 휴무 | F28: =IF(OR($E28="오전반차",$E28="오후반차"),$D$2/2,$D$2) -> 50 | G28: =IF($C28="","",$C28/$F28) | H28: =IF($C28="",IF($E28="","미입력",$E28),IF($C28>=$F28,"달성","미달")) -> 휴무 | I28: =IF(OR($E28="오전반차",$E28="오후반차"),$F$2/2,$F$2) -> 65 | J28: =IF($D28="","",$D28/$I28) | K28: =IF($D28="",IF($E28="","미입력",$E28),IF($D28>=$I28,"달성","미달")) -> 휴무
A29: 46290 | B29: 금 | C29: 16 | D29: 39 | F29: =IF(OR($E29="오전반차",$E29="오후반차"),$D$2/2,$D$2) -> 50 | G29: =IF($C29="","",$C29/$F29) -> 0.32 | H29: =IF($C29="",IF($E29="","미입력",$E29),IF($C29>=$F29,"달성","미달")) -> 미달 | I29: =IF(OR($E29="오전반차",$E29="오후반차"),$F$2/2,$F$2) -> 65 | J29: =IF($D29="","",$D29/$I29) -> 0.6 | K29: =IF($D29="",IF($E29="","미입력",$E29),IF($D29>=$I29,"달성","미달")) -> 미달
A30: 46291 | B30: 토 | C30: 25 | D30: 43 | F30: =IF(OR($E30="오전반차",$E30="오후반차"),$D$2/2,$D$2) -> 50 | G30: =IF($C30="","",$C30/$F30) -> 0.5 | H30: =IF($C30="",IF($E30="","미입력",$E30),IF($C30>=$F30,"달성","미달")) -> 미달 | I30: =IF(OR($E30="오전반차",$E30="오후반차"),$F$2/2,$F$2) -> 65 | J30: =IF($D30="","",$D30/$I30) -> 0.66153846 | K30: =IF($D30="",IF($E30="","미입력",$E30),IF($D30>=$I30,"달성","미달")) -> 미달
A31: 46292 | B31: 일 | E31: 휴무 | F31: =IF(OR($E31="오전반차",$E31="오후반차"),$D$2/2,$D$2) -> 50 | G31: =IF($C31="","",$C31/$F31) | H31: =IF($C31="",IF($E31="","미입력",$E31),IF($C31>=$F31,"달성","미달")) -> 휴무 | I31: =IF(OR($E31="오전반차",$E31="오후반차"),$F$2/2,$F$2) -> 65 | J31: =IF($D31="","",$D31/$I31) | K31: =IF($D31="",IF($E31="","미입력",$E31),IF($D31>=$I31,"달성","미달")) -> 휴무
A32: 46293 | B32: 월 | E32: 휴무 | F32: =IF(OR($E32="오전반차",$E32="오후반차"),$D$2/2,$D$2) -> 50 | G32: =IF($C32="","",$C32/$F32) | H32: =IF($C32="",IF($E32="","미입력",$E32),IF($C32>=$F32,"달성","미달")) -> 휴무 | I32: =IF(OR($E32="오전반차",$E32="오후반차"),$F$2/2,$F$2) -> 65 | J32: =IF($D32="","",$D32/$I32) | K32: =IF($D32="",IF($E32="","미입력",$E32),IF($D32>=$I32,"달성","미달")) -> 휴무
A33: 46294 | B33: 화 | C33: 33 | D33: 32 | F33: =IF(OR($E33="오전반차",$E33="오후반차"),$D$2/2,$D$2) -> 50 | G33: =IF($C33="","",$C33/$F33) -> 0.66 | H33: =IF($C33="",IF($E33="","미입력",$E33),IF($C33>=$F33,"달성","미달")) -> 미달 | I33: =IF(OR($E33="오전반차",$E33="오후반차"),$F$2/2,$F$2) -> 65 | J33: =IF($D33="","",$D33/$I33) -> 0.49230769 | K33: =IF($D33="",IF($E33="","미입력",$E33),IF($D33>=$I33,"달성","미달")) -> 미달
A34: 46295 | B34: 수 | C34: 21 | D34: 42 | F34: =IF(OR($E34="오전반차",$E34="오후반차"),$D$2/2,$D$2) -> 50 | G34: =IF($C34="","",$C34/$F34) -> 0.42 | H34: =IF($C34="",IF($E34="","미입력",$E34),IF($C34>=$F34,"달성","미달")) -> 미달 | I34: =IF(OR($E34="오전반차",$E34="오후반차"),$F$2/2,$F$2) -> 65 | J34: =IF($D34="","",$D34/$I34) -> 0.64615385 | K34: =IF($D34="",IF($E34="","미입력",$E34),IF($D34>=$I34,"달성","미달")) -> 미달
A35: 46296 | B35: 목 | C35: 24 | D35: 34 | F35: =IF(OR($E35="오전반차",$E35="오후반차"),$D$2/2,$D$2) -> 50 | G35: =IF($C35="","",$C35/$F35) -> 0.48 | H35: =IF($C35="",IF($E35="","미입력",$E35),IF($C35>=$F35,"달성","미달")) -> 미달 | I35: =IF(OR($E35="오전반차",$E35="오후반차"),$F$2/2,$F$2) -> 65 | J35: =IF($D35="","",$D35/$I35) -> 0.52307692 | K35: =IF($D35="",IF($E35="","미입력",$E35),IF($D35>=$I35,"달성","미달")) -> 미달
A36: 46297 | B36: 금 | C36: 33 | D36: 64 | F36: =IF(OR($E36="오전반차",$E36="오후반차"),$D$2/2,$D$2) -> 50 | G36: =IF($C36="","",$C36/$F36) -> 0.66 | H36: =IF($C36="",IF($E36="","미입력",$E36),IF($C36>=$F36,"달성","미달")) -> 미달 | I36: =IF(OR($E36="오전반차",$E36="오후반차"),$F$2/2,$F$2) -> 65 | J36: =IF($D36="","",$D36/$I36) -> 0.98461538 | K36: =IF($D36="",IF($E36="","미입력",$E36),IF($D36>=$I36,"달성","미달")) -> 미달
A37: 46298 | B37: 토 | E37: 휴무 | F37: =IF(OR($E37="오전반차",$E37="오후반차"),$D$2/2,$D$2) -> 50 | G37: =IF($C37="","",$C37/$F37) | H37: =IF($C37="",IF($E37="","미입력",$E37),IF($C37>=$F37,"달성","미달")) -> 휴무 | I37: =IF(OR($E37="오전반차",$E37="오후반차"),$F$2/2,$F$2) -> 65 | J37: =IF($D37="","",$D37/$I37) | K37: =IF($D37="",IF($E37="","미입력",$E37),IF($D37>=$I37,"달성","미달")) -> 휴무
A38: 46299 | B38: 일 | E38: 휴무 | F38: =IF(OR($E38="오전반차",$E38="오후반차"),$D$2/2,$D$2) -> 50 | G38: =IF($C38="","",$C38/$F38) | H38: =IF($C38="",IF($E38="","미입력",$E38),IF($C38>=$F38,"달성","미달")) -> 휴무 | I38: =IF(OR($E38="오전반차",$E38="오후반차"),$F$2/2,$F$2) -> 65 | J38: =IF($D38="","",$D38/$I38) | K38: =IF($D38="",IF($E38="","미입력",$E38),IF($D38>=$I38,"달성","미달")) -> 휴무
A39: 46300 | B39: 월 | F39: =IF(OR($E39="오전반차",$E39="오후반차"),$D$2/2,$D$2) -> 50 | G39: =IF($C39="","",$C39/$F39) | H39: =IF($C39="",IF($E39="","미입력",$E39),IF($C39>=$F39,"달성","미달")) -> 미입력 | I39: =IF(OR($E39="오전반차",$E39="오후반차"),$F$2/2,$F$2) -> 65 | J39: =IF($D39="","",$D39/$I39) | K39: =IF($D39="",IF($E39="","미입력",$E39),IF($D39>=$I39,"달성","미달")) -> 미입력
A40: 46301 | B40: 화 | F40: =IF(OR($E40="오전반차",$E40="오후반차"),$D$2/2,$D$2) -> 50 | G40: =IF($C40="","",$C40/$F40) | H40: =IF($C40="",IF($E40="","미입력",$E40),IF($C40>=$F40,"달성","미달")) -> 미입력 | I40: =IF(OR($E40="오전반차",$E40="오후반차"),$F$2/2,$F$2) -> 65 | J40: =IF($D40="","",$D40/$I40) | K40: =IF($D40="",IF($E40="","미입력",$E40),IF($D40>=$I40,"달성","미달")) -> 미입력
...

Sheet 김가은
A1: 1팀 수신·접수 점검표 — 김가은 | M1: 주간 자동집계 — 김가은
A2: 근무연차 | B2: 1년 이상 | C2: 수신 목표 | D2: 50 | E2: 접수 목표 | F2: 65
A3: ※ 노란색 칸(수신 실적 · 접수 실적 · 비고)만 입력하세요. 나머지는 자동 계산됩니다. | M3: ※ 자동 집계 구간입니다. 직접 입력하는 칸은 '주간 피드백내용'(X열) 하나뿐입니다.
A4: 날짜 | B4: 요일 | C4: 수신 실적 | D4: 접수 실적 | E4: 비고 | F4: 수신 목표 | G4: 수신 달성률 | H4: 수신 달성여부 | I4: 접수 목표 | J4: 접수 달성률 | K4: 접수 달성여부 | M4: 주차 | N4: 시작일 | O4: 종료일 | P4: 수신 목표 | Q4: 주간 수신 평균 | R4: 수신 달성률 | S4: 수신 달성여부 | T4: 접수 목표 | U4: 주간 접수 평균 | V4: 접수 달성률 | W4: 접수 달성여부 | X4: 주간 피드백내용
A5: 46266 | B5: 화 | F5: =IF(OR($E5="오전반차",$E5="오후반차"),$D$2/2,$D$2) -> 50 | G5: =IF($C5="","",$C5/$F5) | H5: =IF($C5="",IF($E5="","미입력",$E5),IF($C5>=$F5,"달성","미달")) -> 미입력 | I5: =IF(OR($E5="오전반차",$E5="오후반차"),$F$2/2,$F$2) -> 65 | J5: =IF($D5="","",$D5/$I5) | K5: =IF($D5="",IF($E5="","미입력",$E5),IF($D5>=$I5,"달성","미달")) -> 미입력 | M5: 9월 1주차 | N5: 46266 | O5: 46271 | P5: =IFERROR(SUMPRODUCT(($A$5:$A$126>=$N5)*($A$5:$A$126<=$O5)*ISNUMBER($C$5:$C$126)*$F$5:$F$126)/SUMPRODUCT(($A$5:$A$126>=$N5)*($A$5:$A$126<=$O5)*ISNUMBER($C$5:$C$126)),"") | Q5: =IFERROR(AVERAGEIFS($C$5:$C$126,$A$5:$A$126,">="&$N5,$A$5:$A$126,"<="&$O5),"") | R5: =IF(OR($Q5="",$P5=""),"",$Q5/$P5) | S5: =IF(OR($Q5="",$P5=""),"미입력",IF($Q5>=$P5,"달성","미달")) -> 미입력 | T5: =IFERROR(SUMPRODUCT(($A$5:$A$126>=$N5)*($A$5:$A$126<=$O5)*ISNUMBER($D$5:$D$126)*$I$5:$I$126)/SUMPRODUCT(($A$5:$A$126>=$N5)*($A$5:$A$126<=$O5)*ISNUMBER($D$5:$D$126)),"") | U5: =IFERROR(AVERAGEIFS($D$5:$D$126,$A$5:$A$126,">="&$N5,$A$5:$A$126,"<="&$O5),"") | V5: =IF(OR($U5="",$T5=""),"",$U5/$T5) | W5: =IF(OR($U5="",$T5=""),"미입력",IF($U5>=$T5,"달성","미달")) -> 미입력
A6: 46267 | B6: 수 | F6: =IF(OR($E6="오전반차",$E6="오후반차"),$D$2/2,$D$2) -> 50 | G6: =IF($C6="","",$C6/$F6) | H6: =IF($C6="",IF($E6="","미입력",$E6),IF($C6>=$F6,"달성","미달")) -> 미입력 | I6: =IF(OR($E6="오전반차",$E6="오후반차"),$F$2/2,$F$2) -> 65 | J6: =IF($D6="","",$D6/$I6) | K6: =IF($D6="",IF($E6="","미입력",$E6),IF($D6>=$I6,"달성","미달")) -> 미입력 | M6: 9월 2주차 | N6: 46272 | O6: 46278 | P6: =IFERROR(SUMPRODUCT(($A$5:$A$126>=$N6)*($A$5:$A$126<=$O6)*ISNUMBER($C$5:$C$126)*$F$5:$F$126)/SUMPRODUCT(($A$5:$A$126>=$N6)*($A$5:$A$126<=$O6)*ISNUMBER($C$5:$C$126)),"") | Q6: =IFERROR(AVERAGEIFS($C$5:$C$126,$A$5:$A$126,">="&$N6,$A$5:$A$126,"<="&$O6),"") | R6: =IF(OR($Q6="",$P6=""),"",$Q6/$P6) | S6: =IF(OR($Q6="",$P6=""),"미입력",IF($Q6>=$P6,"달성","미달")) -> 미입력 | T6: =IFERROR(SUMPRODUCT(($A$5:$A$126>=$N6)*($A$5:$A$126<=$O6)*ISNUMBER($D$5:$D$126)*$I$5:$I$126)/SUMPRODUCT(($A$5:$A$126>=$N6)*($A$5:$A$126<=$O6)*ISNUMBER($D$5:$D$126)),"") | U6: =IFERROR(AVERAGEIFS($D$5:$D$126,$A$5:$A$126,">="&$N6,$A$5:$A$126,"<="&$O6),"") | V6: =IF(OR($U6="",$T6=""),"",$U6/$T6) | W6: =IF(OR($U6="",$T6=""),"미입력",IF($U6>=$T6,"달성","미달")) -> 미입력
A7: 46268 | B7: 목 | F7: =IF(OR($E7="오전반차",$E7="오후반차"),$D$2/2,$D$2) -> 50 | G7: =IF($C7="","",$C7/$F7) | H7: =IF($C7="",IF($E7="","미입력",$E7),IF($C7>=$F7,"달성","미달")) -> 미입력 | I7: =IF(OR($E7="오전반차",$E7="오후반차"),$F$2/2,$F$2) -> 65 | J7: =IF($D7="","",$D7/$I7) | K7: =IF($D7="",IF($E7="","미입력",$E7),IF($D7>=$I7,"달성","미달")) -> 미입력 | M7: 9월 3주차 | N7: 46279 | O7: 46285 | P7: =IFERROR(SUMPRODUCT(($A$5:$A$126>=$N7)*($A$5:$A$126<=$O7)*ISNUMBER($C$5:$C$126)*$F$5:$F$126)/SUMPRODUCT(($A$5:$A$126>=$N7)*($A$5:$A$126<=$O7)*ISNUMBER($C$5:$C$126)),"") | Q7: =IFERROR(AVERAGEIFS($C$5:$C$126,$A$5:$A$126,">="&$N7,$A$5:$A$126,"<="&$O7),"") | R7: =IF(OR($Q7="",$P7=""),"",$Q7/$P7) | S7: =IF(OR($Q7="",$P7=""),"미입력",IF($Q7>=$P7,"달성","미달")) -> 미입력 | T7: =IFERROR(SUMPRODUCT(($A$5:$A$126>=$N7)*($A$5:$A$126<=$O7)*ISNUMBER($D$5:$D$126)*$I$5:$I$126)/SUMPRODUCT(($A$5:$A$126>=$N7)*($A$5:$A$126<=$O7)*ISNUMBER($D$5:$D$126)),"") | U7: =IFERROR(AVERAGEIFS($D$5:$D$126,$A$5:$A$126,">="&$N7,$A$5:$A$126,"<="&$O7),"") | V7: =IF(OR($U7="",$T7=""),"",$U7/$T7) | W7: =IF(OR($U7="",$T7=""),"미입력",IF($U7>=$T7,"달성","미달")) -> 미입력
A8: 46269 | B8: 금 | F8: =IF(OR($E8="오전반차",$E8="오후반차"),$D$2/2,$D$2) -> 50 | G8: =IF($C8="","",$C8/$F8) | H8: =IF($C8="",IF($E8="","미입력",$E8),IF($C8>=$F8,"달성","미달")) -> 미입력 | I8: =IF(OR($E8="오전반차",$E8="오후반차"),$F$2/2,$F$2) -> 65 | J8: =IF($D8="","",$D8/$I8) | K8: =IF($D8="",IF($E8="","미입력",$E8),IF($D8>=$I8,"달성","미달")) -> 미입력 | M8: 9월 4주차 | N8: 46286 | O8: 46292 | P8: =IFERROR(SUMPRODUCT(($A$5:$A$126>=$N8)*($A$5:$A$126<=$O8)*ISNUMBER($C$5:$C$126)*$F$5:$F$126)/SUMPRODUCT(($A$5:$A$126>=$N8)*($A$5:$A$126<=$O8)*ISNUMBER($C$5:$C$126)),"") | Q8: =IFERROR(AVERAGEIFS($C$5:$C$126,$A$5:$A$126,">="&$N8,$A$5:$A$126,"<="&$O8),"") | R8: =IF(OR($Q8="",$P8=""),"",$Q8/$P8) | S8: =IF(OR($Q8="",$P8=""),"미입력",IF($Q8>=$P8,"달성","미달")) -> 미입력 | T8: =IFERROR(SUMPRODUCT(($A$5:$A$126>=$N8)*($A$5:$A$126<=$O8)*ISNUMBER($D$5:$D$126)*$I$5:$I$126)/SUMPRODUCT(($A$5:$A$126>=$N8)*($A$5:$A$126<=$O8)*ISNUMBER($D$5:$D$126)),"") | U8: =IFERROR(AVERAGEIFS($D$5:$D$126,$A$5:$A$126,">="&$N8,$A$5:$A$126,"<="&$O8),"") | V8: =IF(OR($U8="",$T8=""),"",$U8/$T8) | W8: =IF(OR($U8="",$T8=""),"미입력",IF($U8>=$T8,"달성","미달")) -> 미입력
A9: 46270 | B9: 토 | F9: =IF(OR($E9="오전반차",$E9="오후반차"),$D$2/2,$D$2) -> 50 | G9: =IF($C9="","",$C9/$F9) | H9: =IF($C9="",IF($E9="","미입력",$E9),IF($C9>=$F9,"달성","미달")) -> 미입력 | I9: =IF(OR($E9="오전반차",$E9="오후반차"),$F$2/2,$F$2) -> 65 | J9: =IF($D9="","",$D9/$I9) | K9: =IF($D9="",IF($E9="","미입력",$E9),IF($D9>=$I9,"달성","미달")) -> 미입력 | M9: 9월 5주차 | N9: 46293 | O9: 46299 | P9: =IFERROR(SUMPRODUCT(($A$5:$A$126>=$N9)*($A$5:$A$126<=$O9)*ISNUMBER($C$5:$C$126)*$F$5:$F$126)/SUMPRODUCT(($A$5:$A$126>=$N9)*($A$5:$A$126<=$O9)*ISNUMBER($C$5:$C$126)),"") -> 50 | Q9: =IFERROR(AVERAGEIFS($C$5:$C$126,$A$5:$A$126,">="&$N9,$A$5:$A$126,"<="&$O9),"") -> 37.75 | R9: =IF(OR($Q9="",$P9=""),"",$Q9/$P9) -> 0.755 | S9: =IF(OR($Q9="",$P9=""),"미입력",IF($Q9>=$P9,"달성","미달")) -> 미달 | T9: =IFERROR(SUMPRODUCT(($A$5:$A$126>=$N9)*($A$5:$A$126<=$O9)*ISNUMBER($D$5:$D$126)*$I$5:$I$126)/SUMPRODUCT(($A$5:$A$126>=$N9)*($A$5:$A$126<=$O9)*ISNUMBER($D$5:$D$126)),"") -> 65 | U9: =IFERROR(AVERAGEIFS($D$5:$D$126,$A$5:$A$126,">="&$N9,$A$5:$A$126,"<="&$O9),"") -> 48.75 | V9: =IF(OR($U9="",$T9=""),"",$U9/$T9) -> 0.75 | W9: =IF(OR($U9="",$T9=""),"미입력",IF($U9>=$T9,"달성","미달")) -> 미달 | X9: 복귀 초기 업무 적응 기간인 만큼 정상 근무 이후 수신·접수 실적이 안정적으로 유지될 수 있도록 피드백 하였습니다
A10: 46271 | B10: 일 | F10: =IF(OR($E10="오전반차",$E10="오후반차"),$D$2/2,$D$2) -> 50 | G10: =IF($C10="","",$C10/$F10) | H10: =IF($C10="",IF($E10="","미입력",$E10),IF($C10>=$F10,"달성","미달")) -> 미입력 | I10: =IF(OR($E10="오전반차",$E10="오후반차"),$F$2/2,$F$2) -> 65 | J10: =IF($D10="","",$D10/$I10) | K10: =IF($D10="",IF($E10="","미입력",$E10),IF($D10>=$I10,"달성","미달")) -> 미입력 | M10: 10월 2주차 | N10: 46300 | O10: 46306 | P10: =IFERROR(SUMPRODUCT(($A$5:$A$126>=$N10)*($A$5:$A$126<=$O10)*ISNUMBER($C$5:$C$126)*$F$5:$F$126)/SUMPRODUCT(($A$5:$A$126>=$N10)*($A$5:$A$126<=$O10)*ISNUMBER($C$5:$C$126)),"") | Q10: =IFERROR(AVERAGEIFS($C$5:$C$126,$A$5:$A$126,">="&$N10,$A$5:$A$126,"<="&$O10),"") | R10: =IF(OR($Q10="",$P10=""),"",$Q10/$P10) | S10: =IF(OR($Q10="",$P10=""),"미입력",IF($Q10>=$P10,"달성","미달")) -> 미입력 | T10: =IFERROR(SUMPRODUCT(($A$5:$A$126>=$N10)*($A$5:$A$126<=$O10)*ISNUMBER($D$5:$D$126)*$I$5:$I$126)/SUMPRODUCT(($A$5:$A$126>=$N10)*($A$5:$A$126<=$O10)*ISNUMBER($D$5:$D$126)),"") | U10: =IFERROR(AVERAGEIFS($D$5:$D$126,$A$5:$A$126,">="&$N10,$A$5:$A$126,"<="&$O10),"") | V10: =IF(OR($U10="",$T10=""),"",$U10/$T10) | W10: =IF(OR($U10="",$T10=""),"미입력",IF($U10>=$T10,"달성","미달")) -> 미입력
A11: 46272 | B11: 월 | F11: =IF(OR($E11="오전반차",$E11="오후반차"),$D$2/2,$D$2) -> 50 | G11: =IF($C11="","",$C11/$F11) | H11: =IF($C11="",IF($E11="","미입력",$E11),IF($C11>=$F11,"달성","미달")) -> 미입력 | I11: =IF(OR($E11="오전반차",$E11="오후반차"),$F$2/2,$F$2) -> 65 | J11: =IF($D11="","",$D11/$I11) | K11: =IF($D11="",IF($E11="","미입력",$E11),IF($D11>=$I11,"달성","미달")) -> 미입력 | M11: 10월 3주차 | N11: 46302 | O11: 46308 | P11: =IFERROR(SUMPRODUCT(($A$5:$A$126>=$N11)*($A$5:$A$126<=$O11)*ISNUMBER($C$5:$C$126)*$F$5:$F$126)/SUMPRODUCT(($A$5:$A$126>=$N11)*($A$5:$A$126<=$O11)*ISNUMBER($C$5:$C$126)),"") | Q11: =IFERROR(AVERAGEIFS($C$5:$C$126,$A$5:$A$126,">="&$N11,$A$5:$A$126,"<="&$O11),"") | R11: =IF(OR($Q11="",$P11=""),"",$Q11/$P11) | S11: =IF(OR($Q11="",$P11=""),"미입력",IF($Q11>=$P11,"달성","미달")) -> 미입력 | T11: =IFERROR(SUMPRODUCT(($A$5:$A$126>=$N11)*($A$5:$A$126<=$O11)*ISNUMBER($D$5:$D$126)*$I$5:$I$126)/SUMPRODUCT(($A$5:$A$126>=$N11)*($A$5:$A$126<=$O11)*ISNUMBER($D$5:$D$126)),"") | U11: =IFERROR(AVERAGEIFS($D$5:$D$126,$A$5:$A$126,">="&$N11,$A$5:$A$126,"<="&$O11),"") | V11: =IF(OR($U11="",$T11=""),"",$U11/$T11) | W11: =IF(OR($U11="",$T11=""),"미입력",IF($U11>=$T11,"달성","미달")) -> 미입력
A12: 46273 | B12: 화 | F12: =IF(OR($E12="오전반차",$E12="오후반차"),$D$2/2,$D$2) -> 50 | G12: =IF($C12="","",$C12/$F12) | H12: =IF($C12="",IF($E12="","미입력",$E12),IF($C12>=$F12,"달성","미달")) -> 미입력 | I12: =IF(OR($E12="오전반차",$E12="오후반차"),$F$2/2,$F$2) -> 65 | J12: =IF($D12="","",$D12/$I12) | K12: =IF($D12="",IF($E12="","미입력",$E12),IF($D12>=$I12,"달성","미달")) -> 미입력 | M12: 10월 4주차 | N12: 46309 | O12: 46315 | P12: =IFERROR(SUMPRODUCT(($A$5:$A$126>=$N12)*($A$5:$A$126<=$O12)*ISNUMBER($C$5:$C$126)*$F$5:$F$126)/SUMPRODUCT(($A$5:$A$126>=$N12)*($A$5:$A$126<=$O12)*ISNUMBER($C$5:$C$126)),"") | Q12: =IFERROR(AVERAGEIFS($C$5:$C$126,$A$5:$A$126,">="&$N12,$A$5:$A$126,"<="&$O12),"") | R12: =IF(OR($Q12="",$P12=""),"",$Q12/$P12) | S12: =IF(OR($Q12="",$P12=""),"미입력",IF($Q12>=$P12,"달성","미달")) -> 미입력 | T12: =IFERROR(SUMPRODUCT(($A$5:$A$126>=$N12)*($A$5:$A$126<=$O12)*ISNUMBER($D$5:$D$126)*$I$5:$I$126)/SUMPRODUCT(($A$5:$A$126>=$N12)*($A$5:$A$126<=$O12)*ISNUMBER($D$5:$D$126)),"") | U12: =IFERROR(AVERAGEIFS($D$5:$D$126,$A$5:$A$126,">="&$N12,$A$5:$A$126,"<="&$O12),"") | V12: =IF(OR($U12="",$T12=""),"",$U12/$T12) | W12: =IF(OR($U12="",$T12=""),"미입력",IF($U12>=$T12,"달성","미달")) -> 미입력
A13: 46274 | B13: 수 | F13: =IF(OR($E13="오전반차",$E13="오후반차"),$D$2/2,$D$2) -> 50 | G13: =IF($C13="","",$C13/$F13) | H13: =IF($C13="",IF($E13="","미입력",$E13),IF($C13>=$F13,"달성","미달")) -> 미입력 | I13: =IF(OR($E13="오전반차",$E13="오후반차"),$F$2/2,$F$2) -> 65 | J13: =IF($D13="","",$D13/$I13) | K13: =IF($D13="",IF($E13="","미입력",$E13),IF($D13>=$I13,"달성","미달")) -> 미입력 | M13: 10월 5주차 | N13: 46316 | O13: 46322 | P13: =IFERROR(SUMPRODUCT(($A$5:$A$126>=$N13)*($A$5:$A$126<=$O13)*ISNUMBER($C$5:$C$126)*$F$5:$F$126)/SUMPRODUCT(($A$5:$A$126>=$N13)*($A$5:$A$126<=$O13)*ISNUMBER($C$5:$C$126)),"") | Q13: =IFERROR(AVERAGEIFS($C$5:$C$126,$A$5:$A$126,">="&$N13,$A$5:$A$126,"<="&$O13),"") | R13: =IF(OR($Q13="",$P13=""),"",$Q13/$P13) | S13: =IF(OR($Q13="",$P13=""),"미입력",IF($Q13>=$P13,"달성","미달")) -> 미입력 | T13: =IFERROR(SUMPRODUCT(($A$5:$A$126>=$N13)*($A$5:$A$126<=$O13)*ISNUMBER($D$5:$D$126)*$I$5:$I$126)/SUMPRODUCT(($A$5:$A$126>=$N13)*($A$5:$A$126<=$O13)*ISNUMBER($D$5:$D$126)),"") | U13: =IFERROR(AVERAGEIFS($D$5:$D$126,$A$5:$A$126,">="&$N13,$A$5:$A$126,"<="&$O13),"") | V13: =IF(OR($U13="",$T13=""),"",$U13/$T13) | W13: =IF(OR($U13="",$T13=""),"미입력",IF($U13>=$T13,"달성","미달")) -> 미입력
A14: 46275 | B14: 목 | F14: =IF(OR($E14="오전반차",$E14="오후반차"),$D$2/2,$D$2) -> 50 | G14: =IF($C14="","",$C14/$F14) | H14: =IF($C14="",IF($E14="","미입력",$E14),IF($C14>=$F14,"달성","미달")) -> 미입력 | I14: =IF(OR($E14="오전반차",$E14="오후반차"),$F$2/2,$F$2) -> 65 | J14: =IF($D14="","",$D14/$I14) | K14: =IF($D14="",IF($E14="","미입력",$E14),IF($D14>=$I14,"달성","미달")) -> 미입력 | N14: 46323 | O14: 46326 | P14: =IFERROR(SUMPRODUCT(($A$5:$A$126>=$N14)*($A$5:$A$126<=$O14)*ISNUMBER($C$5:$C$126)*$F$5:$F$126)/SUMPRODUCT(($A$5:$A$126>=$N14)*($A$5:$A$126<=$O14)*ISNUMBER($C$5:$C$126)),"") | Q14: =IFERROR(AVERAGEIFS($C$5:$C$126,$A$5:$A$126,">="&$N14,$A$5:$A$126,"<="&$O14),"") | R14: =IF(OR($Q14="",$P14=""),"",$Q14/$P14) | S14: =IF(OR($Q14="",$P14=""),"미입력",IF($Q14>=$P14,"달성","미달")) -> 미입력 | T14: =IFERROR(SUMPRODUCT(($A$5:$A$126>=$N14)*($A$5:$A$126<=$O14)*ISNUMBER($D$5:$D$126)*$I$5:$I$126)/SUMPRODUCT(($A$5:$A$126>=$N14)*($A$5:$A$126<=$O14)*ISNUMBER($D$5:$D$126)),"") | U14: =IFERROR(AVERAGEIFS($D$5:$D$126,$A$5:$A$126,">="&$N14,$A$5:$A$126,"<="&$O14),"") | V14: =IF(OR($U14="",$T14=""),"",$U14/$T14) | W14: =IF(OR($U14="",$T14=""),"미입력",IF($U14>=$T14,"달성","미달")) -> 미입력
A15: 46276 | B15: 금 | F15: =IF(OR($E15="오전반차",$E15="오후반차"),$D$2/2,$D$2) -> 50 | G15: =IF($C15="","",$C15/$F15) | H15: =IF($C15="",IF($E15="","미입력",$E15),IF($C15>=$F15,"달성","미달")) -> 미입력 | I15: =IF(OR($E15="오전반차",$E15="오후반차"),$F$2/2,$F$2) -> 65 | J15: =IF($D15="","",$D15/$I15) | K15: =IF($D15="",IF($E15="","미입력",$E15),IF($D15>=$I15,"달성","미달")) -> 미입력 | M15: 11월 1주차 | N15: 46327 | O15: 46332 | P15: =IFERROR(SUMPRODUCT(($A$5:$A$126>=$N15)*($A$5:$A$126<=$O15)*ISNUMBER($C$5:$C$126)*$F$5:$F$126)/SUMPRODUCT(($A$5:$A$126>=$N15)*($A$5:$A$126<=$O15)*ISNUMBER($C$5:$C$126)),"") | Q15: =IFERROR(AVERAGEIFS($C$5:$C$126,$A$5:$A$126,">="&$N15,$A$5:$A$126,"<="&$O15),"") | R15: =IF(OR($Q15="",$P15=""),"",$Q15/$P15) | S15: =IF(OR($Q15="",$P15=""),"미입력",IF($Q15>=$P15,"달성","미달")) -> 미입력 | T15: =IFERROR(SUMPRODUCT(($A$5:$A$126>=$N15)*($A$5:$A$126<=$O15)*ISNUMBER($D$5:$D$126)*$I$5:$I$126)/SUMPRODUCT(($A$5:$A$126>=$N15)*($A$5:$A$126<=$O15)*ISNUMBER($D$5:$D$126)),"") | U15: =IFERROR(AVERAGEIFS($D$5:$D$126,$A$5:$A$126,">="&$N15,$A$5:$A$126,"<="&$O15),"") | V15: =IF(OR($U15="",$T15=""),"",$U15/$T15) | W15: =IF(OR($U15="",$T15=""),"미입력",IF($U15>=$T15,"달성","미달")) -> 미입력
A16: 46277 | B16: 토 | F16: =IF(OR($E16="오전반차",$E16="오후반차"),$D$2/2,$D$2) -> 50 | G16: =IF($C16="","",$C16/$F16) | H16: =IF($C16="",IF($E16="","미입력",$E16),IF($C16>=$F16,"달성","미달")) -> 미입력 | I16: =IF(OR($E16="오전반차",$E16="오후반차"),$F$2/2,$F$2) -> 65 | J16: =IF($D16="","",$D16/$I16) | K16: =IF($D16="",IF($E16="","미입력",$E16),IF($D16>=$I16,"달성","미달")) -> 미입력 | M16: 11월 2주차 | N16: 46333 | O16: 46339 | P16: =IFERROR(SUMPRODUCT(($A$5:$A$126>=$N16)*($A$5:$A$126<=$O16)*ISNUMBER($C$5:$C$126)*$F$5:$F$126)/SUMPRODUCT(($A$5:$A$126>=$N16)*($A$5:$A$126<=$O16)*ISNUMBER($C$5:$C$126)),"") | Q16: =IFERROR(AVERAGEIFS($C$5:$C$126,$A$5:$A$126,">="&$N16,$A$5:$A$126,"<="&$O16),"") | R16: =IF(OR($Q16="",$P16=""),"",$Q16/$P16) | S16: =IF(OR($Q16="",$P16=""),"미입력",IF($Q16>=$P16,"달성","미달")) -> 미입력 | T16: =IFERROR(SUMPRODUCT(($A$5:$A$126>=$N16)*($A$5:$A$126<=$O16)*ISNUMBER($D$5:$D$126)*$I$5:$I$126)/SUMPRODUCT(($A$5:$A$126>=$N16)*($A$5:$A$126<=$O16)*ISNUMBER($D$5:$D$126)),"") | U16: =IFERROR(AVERAGEIFS($D$5:$D$126,$A$5:$A$126,">="&$N16,$A$5:$A$126,"<="&$O16),"") | V16: =IF(OR($U16="",$T16=""),"",$U16/$T16) | W16: =IF(OR($U16="",$T16=""),"미입력",IF($U16>=$T16,"달성","미달")) -> 미입력
A17: 46278 | B17: 일 | F17: =IF(OR($E17="오전반차",$E17="오후반차"),$D$2/2,$D$2) -> 50 | G17: =IF($C17="","",$C17/$F17) | H17: =IF($C17="",IF($E17="","미입력",$E17),IF($C17>=$F17,"달성","미달")) -> 미입력 | I17: =IF(OR($E17="오전반차",$E17="오후반차"),$F$2/2,$F$2) -> 65 | J17: =IF($D17="","",$D17/$I17) | K17: =IF($D17="",IF($E17="","미입력",$E17),IF($D17>=$I17,"달성","미달")) -> 미입력 | M17: 11월 3주차 | N17: 46340 | O17: 46346 | P17: =IFERROR(SUMPRODUCT(($A$5:$A$126>=$N17)*($A$5:$A$126<=$O17)*ISNUMBER($C$5:$C$126)*$F$5:$F$126)/SUMPRODUCT(($A$5:$A$126>=$N17)*($A$5:$A$126<=$O17)*ISNUMBER($C$5:$C$126)),"") | Q17: =IFERROR(AVERAGEIFS($C$5:$C$126,$A$5:$A$126,">="&$N17,$A$5:$A$126,"<="&$O17),"") | R17: =IF(OR($Q17="",$P17=""),"",$Q17/$P17) | S17: =IF(OR($Q17="",$P17=""),"미입력",IF($Q17>=$P17,"달성","미달")) -> 미입력 | T17: =IFERROR(SUMPRODUCT(($A$5:$A$126>=$N17)*($A$5:$A$126<=$O17)*ISNUMBER($D$5:$D$126)*$I$5:$I$126)/SUMPRODUCT(($A$5:$A$126>=$N17)*($A$5:$A$126<=$O17)*ISNUMBER($D$5:$D$126)),"") | U17: =IFERROR(AVERAGEIFS($D$5:$D$126,$A$5:$A$126,">="&$N17,$A$5:$A$126,"<="&$O17),"") | V17: =IF(OR($U17="",$T17=""),"",$U17/$T17) | W17: =IF(OR($U17="",$T17=""),"미입력",IF($U17>=$T17,"달성","미달")) -> 미입력
A18: 46279 | B18: 월 | F18: =IF(OR($E18="오전반차",$E18="오후반차"),$D$2/2,$D$2) -> 50 | G18: =IF($C18="","",$C18/$F18) | H18: =IF($C18="",IF($E18="","미입력",$E18),IF($C18>=$F18,"달성","미달")) -> 미입력 | I18: =IF(OR($E18="오전반차",$E18="오후반차"),$F$2/2,$F$2) -> 65 | J18: =IF($D18="","",$D18/$I18) | K18: =IF($D18="",IF($E18="","미입력",$E18),IF($D18>=$I18,"달성","미달")) -> 미입력 | M18: 11월 4주차 | N18: 46347 | O18: 46353 | P18: =IFERROR(SUMPRODUCT(($A$5:$A$126>=$N18)*($A$5:$A$126<=$O18)*ISNUMBER($C$5:$C$126)*$F$5:$F$126)/SUMPRODUCT(($A$5:$A$126>=$N18)*($A$5:$A$126<=$O18)*ISNUMBER($C$5:$C$126)),"") | Q18: =IFERROR(AVERAGEIFS($C$5:$C$126,$A$5:$A$126,">="&$N18,$A$5:$A$126,"<="&$O18),"") | R18: =IF(OR($Q18="",$P18=""),"",$Q18/$P18) | S18: =IF(OR($Q18="",$P18=""),"미입력",IF($Q18>=$P18,"달성","미달")) -> 미입력 | T18: =IFERROR(SUMPRODUCT(($A$5:$A$126>=$N18)*($A$5:$A$126<=$O18)*ISNUMBER($D$5:$D$126)*$I$5:$I$126)/SUMPRODUCT(($A$5:$A$126>=$N18)*($A$5:$A$126<=$O18)*ISNUMBER($D$5:$D$126)),"") | U18: =IFERROR(AVERAGEIFS($D$5:$D$126,$A$5:$A$126,">="&$N18,$A$5:$A$126,"<="&$O18),"") | V18: =IF(OR($U18="",$T18=""),"",$U18/$T18) | W18: =IF(OR($U18="",$T18=""),"미입력",IF($U18>=$T18,"달성","미달")) -> 미입력
A19: 46280 | B19: 화 | F19: =IF(OR($E19="오전반차",$E19="오후반차"),$D$2/2,$D$2) -> 50 | G19: =IF($C19="","",$C19/$F19) | H19: =IF($C19="",IF($E19="","미입력",$E19),IF($C19>=$F19,"달성","미달")) -> 미입력 | I19: =IF(OR($E19="오전반차",$E19="오후반차"),$F$2/2,$F$2) -> 65 | J19: =IF($D19="","",$D19/$I19) | K19: =IF($D19="",IF($E19="","미입력",$E19),IF($D19>=$I19,"달성","미달")) -> 미입력 | M19: 11월 5주차 | N19: 46354 | O19: 46356 | P19: =IFERROR(SUMPRODUCT(($A$5:$A$126>=$N19)*($A$5:$A$126<=$O19)*ISNUMBER($C$5:$C$126)*$F$5:$F$126)/SUMPRODUCT(($A$5:$A$126>=$N19)*($A$5:$A$126<=$O19)*ISNUMBER($C$5:$C$126)),"") | Q19: =IFERROR(AVERAGEIFS($C$5:$C$126,$A$5:$A$126,">="&$N19,$A$5:$A$126,"<="&$O19),"") | R19: =IF(OR($Q19="",$P19=""),"",$Q19/$P19) | S19: =IF(OR($Q19="",$P19=""),"미입력",IF($Q19>=$P19,"달성","미달")) -> 미입력 | T19: =IFERROR(SUMPRODUCT(($A$5:$A$126>=$N19)*($A$5:$A$126<=$O19)*ISNUMBER($D$5:$D$126)*$I$5:$I$126)/SUMPRODUCT(($A$5:$A$126>=$N19)*($A$5:$A$126<=$O19)*ISNUMBER($D$5:$D$126)),"") | U19: =IFERROR(AVERAGEIFS($D$5:$D$126,$A$5:$A$126,">="&$N19,$A$5:$A$126,"<="&$O19),"") | V19: =IF(OR($U19="",$T19=""),"",$U19/$T19) | W19: =IF(OR($U19="",$T19=""),"미입력",IF($U19>=$T19,"달성","미달")) -> 미입력
A20: 46281 | B20: 수 | F20: =IF(OR($E20="오전반차",$E20="오후반차"),$D$2/2,$D$2) -> 50 | G20: =IF($C20="","",$C20/$F20) | H20: =IF($C20="",IF($E20="","미입력",$E20),IF($C20>=$F20,"달성","미달")) -> 미입력 | I20: =IF(OR($E20="오전반차",$E20="오후반차"),$F$2/2,$F$2) -> 65 | J20: =IF($D20="","",$D20/$I20) | K20: =IF($D20="",IF($E20="","미입력",$E20),IF($D20>=$I20,"달성","미달")) -> 미입력 | M20: 12월 1주차 | N20: 46357 | O20: 46362 | P20: =IFERROR(SUMPRODUCT(($A$5:$A$126>=$N20)*($A$5:$A$126<=$O20)*ISNUMBER($C$5:$C$126)*$F$5:$F$126)/SUMPRODUCT(($A$5:$A$126>=$N20)*($A$5:$A$126<=$O20)*ISNUMBER($C$5:$C$126)),"") | Q20: =IFERROR(AVERAGEIFS($C$5:$C$126,$A$5:$A$126,">="&$N20,$A$5:$A$126,"<="&$O20),"") | R20: =IF(OR($Q20="",$P20=""),"",$Q20/$P20) | S20: =IF(OR($Q20="",$P20=""),"미입력",IF($Q20>=$P20,"달성","미달")) -> 미입력 | T20: =IFERROR(SUMPRODUCT(($A$5:$A$126>=$N20)*($A$5:$A$126<=$O20)*ISNUMBER($D$5:$D$126)*$I$5:$I$126)/SUMPRODUCT(($A$5:$A$126>=$N20)*($A$5:$A$126<=$O20)*ISNUMBER($D$5:$D$126)),"") | U20: =IFERROR(AVERAGEIFS($D$5:$D$126,$A$5:$A$126,">="&$N20,$A$5:$A$126,"<="&$O20),"") | V20: =IF(OR($U20="",$T20=""),"",$U20/$T20) | W20: =IF(OR($U20="",$T20=""),"미입력",IF($U20>=$T20,"달성","미달")) -> 미입력
A21: 46282 | B21: 목 | F21: =IF(OR($E21="오전반차",$E21="오후반차"),$D$2/2,$D$2) -> 50 | G21: =IF($C21="","",$C21/$F21) | H21: =IF($C21="",IF($E21="","미입력",$E21),IF($C21>=$F21,"달성","미달")) -> 미입력 | I21: =IF(OR($E21="오전반차",$E21="오후반차"),$F$2/2,$F$2) -> 65 | J21: =IF($D21="","",$D21/$I21) | K21: =IF($D21="",IF($E21="","미입력",$E21),IF($D21>=$I21,"달성","미달")) -> 미입력 | M21: 12월 2주차 | N21: 46363 | O21: 46369 | P21: =IFERROR(SUMPRODUCT(($A$5:$A$126>=$N21)*($A$5:$A$126<=$O21)*ISNUMBER($C$5:$C$126)*$F$5:$F$126)/SUMPRODUCT(($A$5:$A$126>=$N21)*($A$5:$A$126<=$O21)*ISNUMBER($C$5:$C$126)),"") | Q21: =IFERROR(AVERAGEIFS($C$5:$C$126,$A$5:$A$126,">="&$N21,$A$5:$A$126,"<="&$O21),"") | R21: =IF(OR($Q21="",$P21=""),"",$Q21/$P21) | S21: =IF(OR($Q21="",$P21=""),"미입력",IF($Q21>=$P21,"달성","미달")) -> 미입력 | T21: =IFERROR(SUMPRODUCT(($A$5:$A$126>=$N21)*($A$5:$A$126<=$O21)*ISNUMBER($D$5:$D$126)*$I$5:$I$126)/SUMPRODUCT(($A$5:$A$126>=$N21)*($A$5:$A$126<=$O21)*ISNUMBER($D$5:$D$126)),"") | U21: =IFERROR(AVERAGEIFS($D$5:$D$126,$A$5:$A$126,">="&$N21,$A$5:$A$126,"<="&$O21),"") | V21: =IF(OR($U21="",$T21=""),"",$U21/$T21) | W21: =IF(OR($U21="",$T21=""),"미입력",IF($U21>=$T21,"달성","미달")) -> 미입력
A22: 46283 | B22: 금 | F22: =IF(OR($E22="오전반차",$E22="오후반차"),$D$2/2,$D$2) -> 50 | G22: =IF($C22="","",$C22/$F22) | H22: =IF($C22="",IF($E22="","미입력",$E22),IF($C22>=$F22,"달성","미달")) -> 미입력 | I22: =IF(OR($E22="오전반차",$E22="오후반차"),$F$2/2,$F$2) -> 65 | J22: =IF($D22="","",$D22/$I22) | K22: =IF($D22="",IF($E22="","미입력",$E22),IF($D22>=$I22,"달성","미달")) -> 미입력 | M22: 12월 3주차 | N22: 46370 | O22: 46376 | P22: =IFERROR(SUMPRODUCT(($A$5:$A$126>=$N22)*($A$5:$A$126<=$O22)*ISNUMBER($C$5:$C$126)*$F$5:$F$126)/SUMPRODUCT(($A$5:$A$126>=$N22)*($A$5:$A$126<=$O22)*ISNUMBER($C$5:$C$126)),"") | Q22: =IFERROR(AVERAGEIFS($C$5:$C$126,$A$5:$A$126,">="&$N22,$A$5:$A$126,"<="&$O22),"") | R22: =IF(OR($Q22="",$P22=""),"",$Q22/$P22) | S22: =IF(OR($Q22="",$P22=""),"미입력",IF($Q22>=$P22,"달성","미달")) -> 미입력 | T22: =IFERROR(SUMPRODUCT(($A$5:$A$126>=$N22)*($A$5:$A$126<=$O22)*ISNUMBER($D$5:$D$126)*$I$5:$I$126)/SUMPRODUCT(($A$5:$A$126>=$N22)*($A$5:$A$126<=$O22)*ISNUMBER($D$5:$D$126)),"") | U22: =IFERROR(AVERAGEIFS($D$5:$D$126,$A$5:$A$126,">="&$N22,$A$5:$A$126,"<="&$O22),"") | V22: =IF(OR($U22="",$T22=""),"",$U22/$T22) | W22: =IF(OR($U22="",$T22=""),"미입력",IF($U22>=$T22,"달성","미달")) -> 미입력
A23: 46284 | B23: 토 | F23: =IF(OR($E23="오전반차",$E23="오후반차"),$D$2/2,$D$2) -> 50 | G23: =IF($C23="","",$C23/$F23) | H23: =IF($C23="",IF($E23="","미입력",$E23),IF($C23>=$F23,"달성","미달")) -> 미입력 | I23: =IF(OR($E23="오전반차",$E23="오후반차"),$F$2/2,$F$2) -> 65 | J23: =IF($D23="","",$D23/$I23) | K23: =IF($D23="",IF($E23="","미입력",$E23),IF($D23>=$I23,"달성","미달")) -> 미입력 | M23: 12월 4주차 | N23: 46377 | O23: 46383 | P23: =IFERROR(SUMPRODUCT(($A$5:$A$126>=$N23)*($A$5:$A$126<=$O23)*ISNUMBER($C$5:$C$126)*$F$5:$F$126)/SUMPRODUCT(($A$5:$A$126>=$N23)*($A$5:$A$126<=$O23)*ISNUMBER($C$5:$C$126)),"") | Q23: =IFERROR(AVERAGEIFS($C$5:$C$126,$A$5:$A$126,">="&$N23,$A$5:$A$126,"<="&$O23),"") | R23: =IF(OR($Q23="",$P23=""),"",$Q23/$P23) | S23: =IF(OR($Q23="",$P23=""),"미입력",IF($Q23>=$P23,"달성","미달")) -> 미입력 | T23: =IFERROR(SUMPRODUCT(($A$5:$A$126>=$N23)*($A$5:$A$126<=$O23)*ISNUMBER($D$5:$D$126)*$I$5:$I$126)/SUMPRODUCT(($A$5:$A$126>=$N23)*($A$5:$A$126<=$O23)*ISNUMBER($D$5:$D$126)),"") | U23: =IFERROR(AVERAGEIFS($D$5:$D$126,$A$5:$A$126,">="&$N23,$A$5:$A$126,"<="&$O23),"") | V23: =IF(OR($U23="",$T23=""),"",$U23/$T23) | W23: =IF(OR($U23="",$T23=""),"미입력",IF($U23>=$T23,"달성","미달")) -> 미입력
A24: 46285 | B24: 일 | F24: =IF(OR($E24="오전반차",$E24="오후반차"),$D$2/2,$D$2) -> 50 | G24: =IF($C24="","",$C24/$F24) | H24: =IF($C24="",IF($E24="","미입력",$E24),IF($C24>=$F24,"달성","미달")) -> 미입력 | I24: =IF(OR($E24="오전반차",$E24="오후반차"),$F$2/2,$F$2) -> 65 | J24: =IF($D24="","",$D24/$I24) | K24: =IF($D24="",IF($E24="","미입력",$E24),IF($D24>=$I24,"달성","미달")) -> 미입력 | M24: 12월 5주차 | N24: 46384 | O24: 46387 | P24: =IFERROR(SUMPRODUCT(($A$5:$A$126>=$N24)*($A$5:$A$126<=$O24)*ISNUMBER($C$5:$C$126)*$F$5:$F$126)/SUMPRODUCT(($A$5:$A$126>=$N24)*($A$5:$A$126<=$O24)*ISNUMBER($C$5:$C$126)),"") | Q24: =IFERROR(AVERAGEIFS($C$5:$C$126,$A$5:$A$126,">="&$N24,$A$5:$A$126,"<="&$O24),"") | R24: =IF(OR($Q24="",$P24=""),"",$Q24/$P24) | S24: =IF(OR($Q24="",$P24=""),"미입력",IF($Q24>=$P24,"달성","미달")) -> 미입력 | T24: =IFERROR(SUMPRODUCT(($A$5:$A$126>=$N24)*($A$5:$A$126<=$O24)*ISNUMBER($D$5:$D$126)*$I$5:$I$126)/SUMPRODUCT(($A$5:$A$126>=$N24)*($A$5:$A$126<=$O24)*ISNUMBER($D$5:$D$126)),"") | U24: =IFERROR(AVERAGEIFS($D$5:$D$126,$A$5:$A$126,">="&$N24,$A$5:$A$126,"<="&$O24),"") | V24: =IF(OR($U24="",$T24=""),"",$U24/$T24) | W24: =IF(OR($U24="",$T24=""),"미입력",IF($U24>=$T24,"달성","미달")) -> 미입력
A25: 46286 | B25: 월 | F25: =IF(OR($E25="오전반차",$E25="오후반차"),$D$2/2,$D$2) -> 50 | G25: =IF($C25="","",$C25/$F25) | H25: =IF($C25="",IF($E25="","미입력",$E25),IF($C25>=$F25,"달성","미달")) -> 미입력 | I25: =IF(OR($E25="오전반차",$E25="오후반차"),$F$2/2,$F$2) -> 65 | J25: =IF($D25="","",$D25/$I25) | K25: =IF($D25="",IF($E25="","미입력",$E25),IF($D25>=$I25,"달성","미달")) -> 미입력
A26: 46287 | B26: 화 | F26: =IF(OR($E26="오전반차",$E26="오후반차"),$D$2/2,$D$2) -> 50 | G26: =IF($C26="","",$C26/$F26) | H26: =IF($C26="",IF($E26="","미입력",$E26),IF($C26>=$F26,"달성","미달")) -> 미입력 | I26: =IF(OR($E26="오전반차",$E26="오후반차"),$F$2/2,$F$2) -> 65 | J26: =IF($D26="","",$D26/$I26) | K26: =IF($D26="",IF($E26="","미입력",$E26),IF($D26>=$I26,"달성","미달")) -> 미입력
A27: 46288 | B27: 수 | F27: =IF(OR($E27="오전반차",$E27="오후반차"),$D$2/2,$D$2) -> 50 | G27: =IF($C27="","",$C27/$F27) | H27: =IF($C27="",IF($E27="","미입력",$E27),IF($C27>=$F27,"달성","미달")) -> 미입력 | I27: =IF(OR($E27="오전반차",$E27="오후반차"),$F$2/2,$F$2) -> 65 | J27: =IF($D27="","",$D27/$I27) | K27: =IF($D27="",IF($E27="","미입력",$E27),IF($D27>=$I27,"달성","미달")) -> 미입력
A28: 46289 | B28: 목 | F28: =IF(OR($E28="오전반차",$E28="오후반차"),$D$2/2,$D$2) -> 50 | G28: =IF($C28="","",$C28/$F28) | H28: =IF($C28="",IF($E28="","미입력",$E28),IF($C28>=$F28,"달성","미달")) -> 미입력 | I28: =IF(OR($E28="오전반차",$E28="오후반차"),$F$2/2,$F$2) -> 65 | J28: =IF($D28="","",$D28/$I28) | K28: =IF($D28="",IF($E28="","미입력",$E28),IF($D28>=$I28,"달성","미달")) -> 미입력
A29: 46290 | B29: 금 | F29: =IF(OR($E29="오전반차",$E29="오후반차"),$D$2/2,$D$2) -> 50 | G29: =IF($C29="","",$C29/$F29) | H29: =IF($C29="",IF($E29="","미입력",$E29),IF($C29>=$F29,"달성","미달")) -> 미입력 | I29: =IF(OR($E29="오전반차",$E29="오후반차"),$F$2/2,$F$2) -> 65 | J29: =IF($D29="","",$D29/$I29) | K29: =IF($D29="",IF($E29="","미입력",$E29),IF($D29>=$I29,"달성","미달")) -> 미입력
A30: 46291 | B30: 토 | F30: =IF(OR($E30="오전반차",$E30="오후반차"),$D$2/2,$D$2) -> 50 | G30: =IF($C30="","",$C30/$F30) | H30: =IF($C30="",IF($E30="","미입력",$E30),IF($C30>=$F30,"달성","미달")) -> 미입력 | I30: =IF(OR($E30="오전반차",$E30="오후반차"),$F$2/2,$F$2) -> 65 | J30: =IF($D30="","",$D30/$I30) | K30: =IF($D30="",IF($E30="","미입력",$E30),IF($D30>=$I30,"달성","미달")) -> 미입력
A31: 46292 | B31: 일 | F31: =IF(OR($E31="오전반차",$E31="오후반차"),$D$2/2,$D$2) -> 50 | G31: =IF($C31="","",$C31/$F31) | H31: =IF($C31="",IF($E31="","미입력",$E31),IF($C31>=$F31,"달성","미달")) -> 미입력 | I31: =IF(OR($E31="오전반차",$E31="오후반차"),$F$2/2,$F$2) -> 65 | J31: =IF($D31="","",$D31/$I31) | K31: =IF($D31="",IF($E31="","미입력",$E31),IF($D31>=$I31,"달성","미달")) -> 미입력
A32: 46293 | B32: 월 | F32: =IF(OR($E32="오전반차",$E32="오후반차"),$D$2/2,$D$2) -> 50 | G32: =IF($C32="","",$C32/$F32) | H32: =IF($C32="",IF($E32="","미입력",$E32),IF($C32>=$F32,"달성","미달")) -> 미입력 | I32: =IF(OR($E32="오전반차",$E32="오후반차"),$F$2/2,$F$2) -> 65 | J32: =IF($D32="","",$D32/$I32) | K32: =IF($D32="",IF($E32="","미입력",$E32),IF($D32>=$I32,"달성","미달")) -> 미입력
A33: 46294 | B33: 화 | F33: =IF(OR($E33="오전반차",$E33="오후반차"),$D$2/2,$D$2) -> 50 | G33: =IF($C33="","",$C33/$F33) | H33: =IF($C33="",IF($E33="","미입력",$E33),IF($C33>=$F33,"달성","미달")) -> 미입력 | I33: =IF(OR($E33="오전반차",$E33="오후반차"),$F$2/2,$F$2) -> 65 | J33: =IF($D33="","",$D33/$I33) | K33: =IF($D33="",IF($E33="","미입력",$E33),IF($D33>=$I33,"달성","미달")) -> 미입력
A34: 46295 | B34: 수 | F34: =IF(OR($E34="오전반차",$E34="오후반차"),$D$2/2,$D$2) -> 50 | G34: =IF($C34="","",$C34/$F34) | H34: =IF($C34="",IF($E34="","미입력",$E34),IF($C34>=$F34,"달성","미달")) -> 미입력 | I34: =IF(OR($E34="오전반차",$E34="오후반차"),$F$2/2,$F$2) -> 65 | J34: =IF($D34="","",$D34/$I34) | K34: =IF($D34="",IF($E34="","미입력",$E34),IF($D34>=$I34,"달성","미달")) -> 미입력
A35: 46296 | B35: 목 | C35: 37 | D35: 43 | F35: =IF(OR($E35="오전반차",$E35="오후반차"),$D$2/2,$D$2) -> 50 | G35: =IF($C35="","",$C35/$F35) -> 0.74 | H35: =IF($C35="",IF($E35="","미입력",$E35),IF($C35>=$F35,"달성","미달")) -> 미달 | I35: =IF(OR($E35="오전반차",$E35="오후반차"),$F$2/2,$F$2) -> 65 | J35: =IF($D35="","",$D35/$I35) -> 0.66153846 | K35: =IF($D35="",IF($E35="","미입력",$E35),IF($D35>=$I35,"달성","미달")) -> 미달
A36: 46297 | B36: 금 | C36: 44 | D36: 63 | F36: =IF(OR($E36="오전반차",$E36="오후반차"),$D$2/2,$D$2) -> 50 | G36: =IF($C36="","",$C36/$F36) -> 0.88 | H36: =IF($C36="",IF($E36="","미입력",$E36),IF($C36>=$F36,"달성","미달")) -> 미달 | I36: =IF(OR($E36="오전반차",$E36="오후반차"),$F$2/2,$F$2) -> 65 | J36: =IF($D36="","",$D36/$I36) -> 0.96923077 | K36: =IF($D36="",IF($E36="","미입력",$E36),IF($D36>=$I36,"달성","미달")) -> 미달
A37: 46298 | B37: 토 | C37: 36 | D37: 42 | F37: =IF(OR($E37="오전반차",$E37="오후반차"),$D$2/2,$D$2) -> 50 | G37: =IF($C37="","",$C37/$F37) -> 0.72 | H37: =IF($C37="",IF($E37="","미입력",$E37),IF($C37>=$F37,"달성","미달")) -> 미달 | I37: =IF(OR($E37="오전반차",$E37="오후반차"),$F$2/2,$F$2) -> 65 | J37: =IF($D37="","",$D37/$I37) -> 0.64615385 | K37: =IF($D37="",IF($E37="","미입력",$E37),IF($D37>=$I37,"달성","미달")) -> 미달
A38: 46299 | B38: 일 | C38: 34 | D38: 47 | F38: =IF(OR($E38="오전반차",$E38="오후반차"),$D$2/2,$D$2) -> 50 | G38: =IF($C38="","",$C38/$F38) -> 0.68 | H38: =IF($C38="",IF($E38="","미입력",$E38),IF($C38>=$F38,"달성","미달")) -> 미달 | I38: =IF(OR($E38="오전반차",$E38="오후반차"),$F$2/2,$F$2) -> 65 | J38: =IF($D38="","",$D38/$I38) -> 0.72307692 | K38: =IF($D38="",IF($E38="","미입력",$E38),IF($D38>=$I38,"달성","미달")) -> 미달
